Workbook

Sheet README
A1: Discord Nitro subscription revenue model (portfolio project). All Discord figures are third-party estimates.
A2: Scenario: upside. Generated by nitro_model.excel_export from data/assumptions.csv; mirrors src/nitro_model/cohorts.py.
A3: Flow: Assumptions -> Params -> Curves / Eras / MAU / Prices / FX -> Adds -> Paid, Legacy, React -> Subs -> Revenue -> Checks.
A4: FY2025 is history (base values, Params hist.*). From Params!forecast_start_month_index the scenario's values apply to new sign-ups.
A5: Change inputs only on the Assumptions sheet (yellow cells on Params link there). Params!k_cal is solved in Python.
A6: Active subscribers = SUMPRODUCT(sign-ups to date, reversed survival curve). Cohort_US_NitroM shows one segment as a full triangle.
A7: Prices are fixed in local currency at FY2025 average FX; the FX sheet turns them into USD each month (Params!fx_shock_dir: +1 = USD 10% stronger).

Sheet Assumptions
A1: id | B1: group | C1: segment | D1: scenario | E1: value | F1: unit | G1: low | H1: high | I1: status | J1: source_ids | K1: as_of | L1: notes
A2: model_start_year | B2: timeline | C2: all | D2: all | E2: 2025 | F2: year | I2: design | J2: P01 | K2: 2026-10-27 | L2: FY2025 is the calibration year against public estimates
A3: model_start_month | B3: timeline | C3: all | D3: all | E3: 1 | F3: month | I3: design | J3: P01 | K3: 2026-10-27
A4: horizon_months | B4: timeline | C4: all | D4: all | E4: 72 | F4: months | I4: design | J4: P01 | K4: 2026-10-27 | L4: Jan 2025 to Dec 2030: 12 calibration months + 60 forecast months
A5: mau_jan2025 | B5: mau | C5: all | D5: all | E5: 225 | F5: M users | G5: 200 | H5: 260 | I5: proposed | J5: S06;S02;S03;A01 | K5: 2026-10-27 | L5: Discord says 200M+ (May 2025); trackers say 227.7M (2024) to 250-259M (2025). Start below tracker midpoint: trackers likely mix visits and registered users
A6: mau_share | B6: mau | C6: US_CA | D6: all | E6: 0.31 | F6: share | G6: 0.27 | H6: 0.35 | I6: proposed | J6: S07;A01 | K6: 2026-10-27 | L6: Semrush web traffic US 29.1% plus Canada. Caveat: web traffic misses desktop-app and mobile-app use so regional mix may skew; conv_rate by region absorbs part of the error
A7: mau_share | B7: mau | C7: EUROPE | D7: all | E7: 0.28 | F7: share | G7: 0.22 | H7: 0.32 | I7: proposed | J7: S07;A01 | K7: 2026-10-27 | L7: No direct Europe figure found; judgment from country traffic tail (DE/FR/UK/PL)
A8: mau_share | B8: mau | C8: LATAM | D8: all | E8: 0.14 | F8: share | G8: 0.1 | H8: 0.18 | I8: proposed | J8: S07;A01 | K8: 2026-10-27 | L8: Brazil 7.25% of traffic plus rest of LatAm
A9: mau_share | B9: mau | C9: APAC | D9: all | E9: 0.15 | F9: share | G9: 0.1 | H9: 0.2 | I9: proposed | J9: S07;A01 | K9: 2026-10-27 | L9: India 4.9% of traffic plus Japan/SEA/ANZ
A10: mau_share | B10: mau | C10: ROW | D10: all | E10: 0.12 | F10: share | G10: 0.08 | H10: 0.16 | I10: proposed | J10: S07;A01 | K10: 2026-10-27 | L10: Turkey, Russia, MENA, Africa
A11: mau_growth_2025 | B11: mau | C11: all | D11: all | E11: 0.1 | F11: YoY | G11: 0.06 | H11: 0.14 | I11: proposed | J11: S02;S03;A01 | K11: 2026-10-28 | L11: Tracker YoY 2024-25: 8.7% (Resourcera) to 13.8% (Feedough). Same in every scenario: FY2025 is the calibration year
A12: mau_growth_first | B12: mau | C12: all | D12: base | E12: 0.08 | F12: YoY | G12: 0.05 | H12: 0.11 | I12: proposed | J12: S02;S03;A01 | K12: 2026-10-28 | L12: Applies to 2026, the first forecast year; fades linearly to mau_growth_last by 2030
A13: mau_growth_first | B13: mau | C13: all | D13: upside | E13: 0.11 | F13: YoY | G13: 0.08 | H13: 0.14 | I13: proposed | J13: S02;A01 | K13: 2026-10-28 | L13: Near the high tracker growth rate
A14: mau_growth_first | B14: mau | C14: all | D14: downside | E14: 0.05 | F14: YoY | G14: 0.02 | H14: 0.08 | I14: proposed | J14: A01 | K14: 2026-10-28
A15: mau_growth_last | B15: mau | C15: all | D15: base | E15: 0.04 | F15: YoY | G15: 0.02 | H15: 0.06 | I15: proposed | J15: A01 | K15: 2026-10-27 | L15: Applies to 2030; linear fade from first-year growth
A16: mau_growth_last | B16: mau | C16: all | D16: upside | E16: 0.06 | F16: YoY | G16: 0.04 | H16: 0.08 | I16: proposed | J16: A01 | K16: 2026-10-27
A17: mau_growth_last | B17: mau | C17: all | D17: downside | E17: 0 | F17: YoY | G17: -0.03 | H17: 0.02 | I17: proposed | J17: A01 | K17: 2026-10-27 | L17: Flat MAU by 2030
A18: conv_rate | B18: conversion | C18: US_CA | D18: all | E18: 0.0045 | F18: gross adds / MAU / month | G18: 0.003 | H18: 0.006 | I18: proposed | J18: A01 | K18: 2026-10-27 | L18: Back-solved: ~0.65M gross adds/mo holds ~7.3M subs at a ~13-month blended lifetime. Split by willingness to pay. Recalibrated in M3
A19: conv_rate | B19: conversion | C19: EUROPE | D19: all | E19: 0.0032 | F19: gross adds / MAU / month | G19: 0.002 | H19: 0.0045 | I19: proposed | J19: A01 | K19: 2026-10-27
A20: conv_rate | B20: conversion | C20: LATAM | D20: all | E20: 0.0015 | F20: gross adds / MAU / month | G20: 0.0008 | H20: 0.0025 | I20: proposed | J20: A01 | K20: 2026-10-27
A21: conv_rate | B21: conversion | C21: APAC | D21: all | E21: 0.0018 | F21: gross adds / MAU / month | G21: 0.001 | H21: 0.0028 | I21: proposed | J21: A01 | K21: 2026-10-27
A22: conv_rate | B22: conversion | C22: ROW | D22: all | E22: 0.0015 | F22: gross adds / MAU / month | G22: 0.0008 | H22: 0.0025 | I22: proposed | J22: A01 | K22: 2026-10-27
A23: conv_multiplier | B23: conversion | C23: all | D23: base | E23: 1 | F23: x | I23: design | J23: P01 | K23: 2026-10-27
A24: conv_multiplier | B24: conversion | C24: all | D24: upside | E24: 1.1 | F24: x | G24: 1.05 | H24: 1.2 | I24: proposed | J24: A01 | K24: 2026-10-27
A25: conv_multiplier | B25: conversion | C25: all | D25: downside | E25: 0.9 | F25: x | G25: 0.8 | H25: 0.95 | I25: proposed | J25: A01 | K25: 2026-10-27
A26: plan_mix | B26: mix_plan | C26: NITRO_M | D26: all | E26: 0.45 | F26: share of gross adds | G26: 0.35 | H26: 0.55 | I26: proposed | J26: A01 | K26: 2026-10-27 | L26: No public plan mix. Drives most of the ARPU gap vs list price
A27: plan_mix | B27: mix_plan | C27: NITRO_A | D27: all | E27: 0.15 | F27: share of gross adds | G27: 0.08 | H27: 0.25 | I27: proposed | J27: S15;A01 | K27: 2026-10-27 | L27: Duolingo shows annual share can reach 47-71% when pushed hard; Discord does not push annual that hard
A28: plan_mix | B28: mix_plan | C28: BASIC_M | D28: all | E28: 0.32 | F28: share of gross adds | G28: 0.2 | H28: 0.45 | I28: proposed | J28: A01 | K28: 2026-10-27
A29: plan_mix | B29: mix_plan | C29: BASIC_A | D29: all | E29: 0.08 | F29: share of gross adds | G29: 0.03 | H29: 0.15 | I29: proposed | J29: A01 | K29: 2026-10-27
A30: platform_mix | B30: mix_platform | C30: US_CA|WEB | D30: all | E30: 0.55 | F30: share of gross adds | G30: 0.45 | H30: 0.65 | I30: proposed | J30: A01 | K30: 2026-10-27 | L30: Desktop-first product; web/desktop billing avoids app store fees
A31: platform_mix | B31: mix_platform | C31: US_CA|IOS | D31: all | E31: 0.3 | F31: share of gross adds | G31: 0.2 | H31: 0.4 | I31: proposed | J31: A01 | K31: 2026-10-27 | L31: High iPhone share in US
A32: platform_mix | B32: mix_platform | C32: US_CA|ANDROID | D32: all | E32: 0.15 | F32: share of gross adds | G32: 0.1 | H32: 0.2 | I32: proposed | J32: A01 | K32: 2026-10-27
A33: platform_mix | B33: mix_platform | C33: EUROPE|WEB | D33: all | E33: 0.6 | F33: share of gross adds | G33: 0.5 | H33: 0.7 | I33: proposed | J33: A01 | K33: 2026-10-27
A34: platform_mix | B34: mix_platform | C34: EUROPE|IOS | D34: all | E34: 0.22 | F34: share of gross adds | G34: 0.15 | H34: 0.3 | I34: proposed | J34: A01 | K34: 2026-10-27
A35: platform_mix | B35: mix_platform | C35: EUROPE|ANDROID | D35: all | E35: 0.18 | F35: share of gross adds | G35: 0.12 | H35: 0.25 | I35: proposed | J35: A01 | K35: 2026-10-27
A36: platform_mix | B36: mix_platform | C36: LATAM|WEB | D36: all | E36: 0.55 | F36: share of gross adds | G36: 0.45 | H36: 0.65 | I36: proposed | J36: A01 | K36: 2026-10-27
A37: platform_mix | B37: mix_platform | C37: LATAM|IOS | D37: all | E37: 0.1 | F37: share of gross adds | G37: 0.05 | H37: 0.15 | I37: proposed | J37: A01 | K37: 2026-10-27 | L37: Android-dominant region
A38: platform_mix | B38: mix_platform | C38: LATAM|ANDROID | D38: all | E38: 0.35 | F38: share of gross adds | G38: 0.25 | H38: 0.45 | I38: proposed | J38: A01 | K38: 2026-10-27
A39: platform_mix | B39: mix_platform | C39: APAC|WEB | D39: all | E39: 0.55 | F39: share of gross adds | G39: 0.45 | H39: 0.65 | I39: proposed | J39: A01 | K39: 2026-10-27
A40: platform_mix | B40: mix_platform | C40: APAC|IOS | D40: all | E40: 0.2 | F40: share of gross adds | G40: 0.1 | H40: 0.3 | I40: proposed | J40: A01 | K40: 2026-10-27 | L40: Japan iOS-heavy; India Android-heavy
...

Sheet Params
A1: param | B1: value | C1: linked to
A2: mau0 | B2: =Assumptions!$E$5*1e+06 | C2: mau_jan2025[all]
A3: mau_growth_2025 | B3: =Assumptions!$E$11 | C3: mau_growth_2025[all]
A4: mau_growth_first | B4: =Assumptions!$E$13 | C4: mau_growth_first[all]
A5: mau_growth_last | B5: =Assumptions!$E$16 | C5: mau_growth_last[all]
A6: trial_months | B6: =Assumptions!$E$95 | C6: trial_months[all]
A7: count_trials_as_subs | B7: =Assumptions!$E$99 | C7: count_trials_as_subs[all]
A8: forecast_start_month_index | B8: =Assumptions!$E$122 | C8: forecast_start_month_index[all]
A9: exp_enabled | B9: =Assumptions!$E$129 | C9: exp_enabled[all]
A10: exp_start_month_index | B10: =Assumptions!$E$130 | C10: exp_start_month_index[all]
A11: exp_conv_lift | B11: =Assumptions!$E$131 | C11: exp_conv_lift[all]
A12: exp_churn_change | B12: =Assumptions!$E$132 | C12: exp_churn_change[all]
A13: exp_price_change | B13: =Assumptions!$E$133 | C13: exp_price_change[all]
A14: open_subs | B14: =Assumptions!$E$68*1e+06 | C14: open_subs[all]
A15: open_churn_tail | B15: =Assumptions!$E$79 | C15: open_churn_tail[MONTHLY]
A16: open_y1_share | B16: =Assumptions!$E$78 | C16: open_y1_share[all]
A17: avg_discount | B17: =Assumptions!$E$100 | C17: avg_discount[all]
A18: fee_web | B18: =Assumptions!$E$104 | C18: store_fee[WEB]
A19: fee_ios_y1 | B19: =Assumptions!$E$101 | C19: store_fee[IOS_Y1]
A20: fee_ios_later | B20: =Assumptions!$E$102 | C20: store_fee[IOS_LATER]
A21: fee_android | B21: =Assumptions!$E$103 | C21: store_fee[ANDROID]
A22: cal_target_subs | B22: =Assumptions!$E$134*1e+06 | C22: cal_subs_mid2025[all]
A23: cal_month_index | B23: =Assumptions!$E$135 | C23: cal_month_index[all]
A24: fx_shock | B24: =Assumptions!$E$128 | C24: fx_shock[all]
A25: fx_spot_month_index | B25: =Assumptions!$E$121 | C25: fx_spot_month_index[all]
A26: hist.conv_multiplier | B26: =Assumptions!$E$23 | C26: conv_multiplier[all]
A27: conv_multiplier | B27: =Assumptions!$E$24 | C27: conv_multiplier[all]
A28: hist.trial_share | B28: =Assumptions!$E$94 | C28: trial_share[all]
A29: trial_share | B29: =Assumptions!$E$94 | C29: trial_share[all]
A30: hist.trial_to_paid | B30: =Assumptions!$E$96 | C30: trial_to_paid[all]
A31: trial_to_paid | B31: =Assumptions!$E$97 | C31: trial_to_paid[all]
A32: hist.churn_m1 | B32: =Assumptions!$E$45 | C32: churn_m1[MONTHLY]
A33: churn_m1 | B33: =Assumptions!$E$46 | C33: churn_m1[MONTHLY]
A34: hist.churn_m2 | B34: =Assumptions!$E$48 | C34: churn_m2[MONTHLY]
A35: churn_m2 | B35: =Assumptions!$E$49 | C35: churn_m2[MONTHLY]
A36: hist.churn_m3 | B36: =Assumptions!$E$51 | C36: churn_m3[MONTHLY]
A37: churn_m3 | B37: =Assumptions!$E$52 | C37: churn_m3[MONTHLY]
A38: hist.churn_tail | B38: =Assumptions!$E$54 | C38: churn_tail[MONTHLY]
A39: churn_tail | B39: =Assumptions!$E$55 | C39: churn_tail[MONTHLY]
A40: hist.annual_renewal_first | B40: =Assumptions!$E$57 | C40: annual_renewal_first[ANNUAL]
...

Sheet Curves
A1: curve | B1: age (months) -> | C1: 0 | D1: 1 | E1: 2 | F1: 3 | G1: 4 | H1: 5 | I1: 6 | J1: 7 | K1: 8 | L1: 9 | M1: 10 | N1: 11 | O1: 12 | P1: 13 | Q1: 14 | R1: 15 | S1: 16 | T1: 17 | U1: 18 | V1: 19 | W1: 20 | X1: 21 | Y1: 22 | Z1: 23 | AA1: 24 | AB1: 25 | AC1: 26 | AD1: 27 | AE1: 28 | AF1: 29 | AG1: 30 | AH1: 31 | AI1: 32 | AJ1: 33 | AK1: 34 | AL1: 35 | AM1: 36 | AN1: 37 | AO1: 38 | AP1: 39 | AQ1: 40 | AR1: 41 | AS1: 42 | AT1: 43 | AU1: 44 | AV1: 45 | AW1: 46 | AX1: 47 | AY1: 48 | AZ1: 49 | BA1: 50 | BB1: 51 | BC1: 52 | BD1: 53 | BE1: 54 | BF1: 55 | BG1: 56 | BH1: 57 | BI1: 58 | BJ1: 59 | BK1: 60 | BL1: 61 | BM1: 62 | BN1: 63 | BO1: 64 | BP1: 65 | BQ1: 66 | BR1: 67 | BS1: 68 | BT1: 69 | BU1: 70 | BV1: 71
A2: Reversed rows run oldest age first so SUMPRODUCT can pair them with sign-ups to date.
A3: @0: history
A4: S_MONTHLY@0 | C4: =1 | D4: =C4*(1-IF(D$1=1,Params!$B$32,IF(D$1=2,Params!$B$34,IF(D$1=3,Params!$B$36,Params!$B$38)))) | E4: =D4*(1-IF(E$1=1,Params!$B$32,IF(E$1=2,Params!$B$34,IF(E$1=3,Params!$B$36,Params!$B$38)))) | F4: =E4*(1-IF(F$1=1,Params!$B$32,IF(F$1=2,Params!$B$34,IF(F$1=3,Params!$B$36,Params!$B$38)))) | G4: =F4*(1-IF(G$1=1,Params!$B$32,IF(G$1=2,Params!$B$34,IF(G$1=3,Params!$B$36,Params!$B$38)))) | H4: =G4*(1-IF(H$1=1,Params!$B$32,IF(H$1=2,Params!$B$34,IF(H$1=3,Params!$B$36,Params!$B$38)))) | I4: =H4*(1-IF(I$1=1,Params!$B$32,IF(I$1=2,Params!$B$34,IF(I$1=3,Params!$B$36,Params!$B$38)))) | J4: =I4*(1-IF(J$1=1,Params!$B$32,IF(J$1=2,Params!$B$34,IF(J$1=3,Params!$B$36,Params!$B$38)))) | K4: =J4*(1-IF(K$1=1,Params!$B$32,IF(K$1=2,Params!$B$34,IF(K$1=3,Params!$B$36,Params!$B$38)))) | ... BV4: =BU4*(1-IF(BV$1=1,Params!$B$32,IF(BV$1=2,Params!$B$34,IF(BV$1=3,Params!$B$36,Params!$B$38))))
A5: S_ANNUAL@0 | C5: =IF(C$1<12,1,Params!$B$40*Params!$B$42^(INT(C$1/12)-1)) | D5: =IF(D$1<12,1,Params!$B$40*Params!$B$42^(INT(D$1/12)-1)) | E5: =IF(E$1<12,1,Params!$B$40*Params!$B$42^(INT(E$1/12)-1)) | F5: =IF(F$1<12,1,Params!$B$40*Params!$B$42^(INT(F$1/12)-1)) | G5: =IF(G$1<12,1,Params!$B$40*Params!$B$42^(INT(G$1/12)-1)) | H5: =IF(H$1<12,1,Params!$B$40*Params!$B$42^(INT(H$1/12)-1)) | I5: =IF(I$1<12,1,Params!$B$40*Params!$B$42^(INT(I$1/12)-1)) | J5: =IF(J$1<12,1,Params!$B$40*Params!$B$42^(INT(J$1/12)-1)) | ... BV5: =IF(BV$1<12,1,Params!$B$40*Params!$B$42^(INT(BV$1/12)-1))
A6: D_MONTHLY@0 | C6: =0 | D6: =C4-D4 | E6: =D4-E4 | F6: =E4-F4 | G6: =F4-G4 | H6: =G4-H4 | I6: =H4-I4 | J6: =I4-J4 | K6: =J4-K4 | ... BV6: =BU4-BV4
A7: D_ANNUAL@0 | C7: =0 | D7: =C5-D5 | E7: =D5-E5 | F7: =E5-F5 | G7: =F5-G5 | H7: =G5-H5 | I7: =H5-I5 | J7: =I5-J5 | K7: =J5-K5 | ... BV7: =BU5-BV5
A8: S_REACT@0 | C8: =(1-Params!$B$48)^C$1 | D8: =(1-Params!$B$48)^D$1 | E8: =(1-Params!$B$48)^E$1 | F8: =(1-Params!$B$48)^F$1 | G8: =(1-Params!$B$48)^G$1 | H8: =(1-Params!$B$48)^H$1 | I8: =(1-Params!$B$48)^I$1 | J8: =(1-Params!$B$48)^J$1 | ... BV8: =(1-Params!$B$48)^BV$1
A9: D_REACT@0 | C9: =0 | D9: =C8-D8 | E9: =D8-E8 | F9: =E8-F8 | G9: =F8-G8 | H9: =G8-H8 | I9: =H8-I8 | J9: =I8-J8 | K9: =J8-K8 | ... BV9: =BU8-BV8
A10: K_REACT@0 | C10: =IF(AND(C$1>=1,C$1<=Params!$B$46),Params!$B$44*(1-Params!$B$44)^(C$1-1),0) | D10: =IF(AND(D$1>=1,D$1<=Params!$B$46),Params!$B$44*(1-Params!$B$44)^(D$1-1),0) | E10: =IF(AND(E$1>=1,E$1<=Params!$B$46),Params!$B$44*(1-Params!$B$44)^(E$1-1),0) | F10: =IF(AND(F$1>=1,F$1<=Params!$B$46),Params!$B$44*(1-Params!$B$44)^(F$1-1),0) | G10: =IF(AND(G$1>=1,G$1<=Params!$B$46),Params!$B$44*(1-Params!$B$44)^(G$1-1),0) | H10: =IF(AND(H$1>=1,H$1<=Params!$B$46),Params!$B$44*(1-Params!$B$44)^(H$1-1),0) | I10: =IF(AND(I$1>=1,I$1<=Params!$B$46),Params!$B$44*(1-Params!$B$44)^(I$1-1),0) | J10: =IF(AND(J$1>=1,J$1<=Params!$B$46),Params!$B$44*(1-Params!$B$44)^(J$1-1),0) | ... BV10: =IF(AND(BV$1>=1,BV$1<=Params!$B$46),Params!$B$44*(1-Params!$B$44)^(BV$1-1),0)
A11: S_MONTHLY_Y1@0 | C11: =IF(C$1<12,C4,0) | D11: =IF(D$1<12,D4,0) | E11: =IF(E$1<12,E4,0) | F11: =IF(F$1<12,F4,0) | G11: =IF(G$1<12,G4,0) | H11: =IF(H$1<12,H4,0) | I11: =IF(I$1<12,I4,0) | J11: =IF(J$1<12,J4,0) | ... BV11: =IF(BV$1<12,BV4,0)
A12: S_ANNUAL_Y1@0 | C12: =IF(C$1<12,C5,0) | D12: =IF(D$1<12,D5,0) | E12: =IF(E$1<12,E5,0) | F12: =IF(F$1<12,F5,0) | G12: =IF(G$1<12,G5,0) | H12: =IF(H$1<12,H5,0) | I12: =IF(I$1<12,I5,0) | J12: =IF(J$1<12,J5,0) | ... BV12: =IF(BV$1<12,BV5,0)
A13: S_REACT_Y1@0 | C13: =IF(C$1<12,C8,0) | D13: =IF(D$1<12,D8,0) | E13: =IF(E$1<12,E8,0) | F13: =IF(F$1<12,F8,0) | G13: =IF(G$1<12,G8,0) | H13: =IF(H$1<12,H8,0) | I13: =IF(I$1<12,I8,0) | J13: =IF(J$1<12,J8,0) | ... BV13: =IF(BV$1<12,BV8,0)
A15: S_MONTHLY@0 reversed | C15: =INDEX($C$4:$BV$4,72) | D15: =INDEX($C$4:$BV$4,71) | E15: =INDEX($C$4:$BV$4,70) | F15: =INDEX($C$4:$BV$4,69) | G15: =INDEX($C$4:$BV$4,68) | H15: =INDEX($C$4:$BV$4,67) | I15: =INDEX($C$4:$BV$4,66) | J15: =INDEX($C$4:$BV$4,65) | K15: =INDEX($C$4:$BV$4,64) | L15: =INDEX($C$4:$BV$4,63) | M15: =INDEX($C$4:$BV$4,62) | N15: =INDEX($C$4:$BV$4,61) | O15: =INDEX($C$4:$BV$4,60) | P15: =INDEX($C$4:$BV$4,59) | Q15: =INDEX($C$4:$BV$4,58) | R15: =INDEX($C$4:$BV$4,57) | S15: =INDEX($C$4:$BV$4,56) | T15: =INDEX($C$4:$BV$4,55) | U15: =INDEX($C$4:$BV$4,54) | V15: =INDEX($C$4:$BV$4,53) | W15: =INDEX($C$4:$BV$4,52) | X15: =INDEX($C$4:$BV$4,51) | Y15: =INDEX($C$4:$BV$4,50) | Z15: =INDEX($C$4:$BV$4,49) | AA15: =INDEX($C$4:$BV$4,48) | AB15: =INDEX($C$4:$BV$4,47) | AC15: =INDEX($C$4:$BV$4,46) | AD15: =INDEX($C$4:$BV$4,45) | AE15: =INDEX($C$4:$BV$4,44) | AF15: =INDEX($C$4:$BV$4,43) | AG15: =INDEX($C$4:$BV$4,42) | AH15: =INDEX($C$4:$BV$4,41) | AI15: =INDEX($C$4:$BV$4,40) | AJ15: =INDEX($C$4:$BV$4,39) | AK15: =INDEX($C$4:$BV$4,38) | AL15: =INDEX($C$4:$BV$4,37) | AM15: =INDEX($C$4:$BV$4,36) | AN15: =INDEX($C$4:$BV$4,35) | AO15: =INDEX($C$4:$BV$4,34) | AP15: =INDEX($C$4:$BV$4,33) | AQ15: =INDEX($C$4:$BV$4,32) | AR15: =INDEX($C$4:$BV$4,31) | AS15: =INDEX($C$4:$BV$4,30) | AT15: =INDEX($C$4:$BV$4,29) | AU15: =INDEX($C$4:$BV$4,28) | AV15: =INDEX($C$4:$BV$4,27) | AW15: =INDEX($C$4:$BV$4,26) | AX15: =INDEX($C$4:$BV$4,25) | AY15: =INDEX($C$4:$BV$4,24) | AZ15: =INDEX($C$4:$BV$4,23) | BA15: =INDEX($C$4:$BV$4,22) | BB15: =INDEX($C$4:$BV$4,21) | BC15: =INDEX($C$4:$BV$4,20) | BD15: =INDEX($C$4:$BV$4,19) | BE15: =INDEX($C$4:$BV$4,18) | BF15: =INDEX($C$4:$BV$4,17) | BG15: =INDEX($C$4:$BV$4,16) | BH15: =INDEX($C$4:$BV$4,15) | BI15: =INDEX($C$4:$BV$4,14) | BJ15: =INDEX($C$4:$BV$4,13) | BK15: =INDEX($C$4:$BV$4,12) | BL15: =INDEX($C$4:$BV$4,11) | BM15: =INDEX($C$4:$BV$4,10) | BN15: =INDEX($C$4:$BV$4,9) | BO15: =INDEX($C$4:$BV$4,8) | BP15: =INDEX($C$4:$BV$4,7) | BQ15: =INDEX($C$4:$BV$4,6) | BR15: =INDEX($C$4:$BV$4,5) | BS15: =INDEX($C$4:$BV$4,4) | BT15: =INDEX($C$4:$BV$4,3) | BU15: =INDEX($C$4:$BV$4,2) | BV15: =INDEX($C$4:$BV$4,1)
A16: S_ANNUAL@0 reversed | C16: =INDEX($C$5:$BV$5,72) | D16: =INDEX($C$5:$BV$5,71) | E16: =INDEX($C$5:$BV$5,70) | F16: =INDEX($C$5:$BV$5,69) | G16: =INDEX($C$5:$BV$5,68) | H16: =INDEX($C$5:$BV$5,67) | I16: =INDEX($C$5:$BV$5,66) | J16: =INDEX($C$5:$BV$5,65) | K16: =INDEX($C$5:$BV$5,64) | L16: =INDEX($C$5:$BV$5,63) | M16: =INDEX($C$5:$BV$5,62) | N16: =INDEX($C$5:$BV$5,61) | O16: =INDEX($C$5:$BV$5,60) | P16: =INDEX($C$5:$BV$5,59) | Q16: =INDEX($C$5:$BV$5,58) | R16: =INDEX($C$5:$BV$5,57) | S16: =INDEX($C$5:$BV$5,56) | T16: =INDEX($C$5:$BV$5,55) | U16: =INDEX($C$5:$BV$5,54) | V16: =INDEX($C$5:$BV$5,53) | W16: =INDEX($C$5:$BV$5,52) | X16: =INDEX($C$5:$BV$5,51) | Y16: =INDEX($C$5:$BV$5,50) | Z16: =INDEX($C$5:$BV$5,49) | AA16: =INDEX($C$5:$BV$5,48) | AB16: =INDEX($C$5:$BV$5,47) | AC16: =INDEX($C$5:$BV$5,46) | AD16: =INDEX($C$5:$BV$5,45) | AE16: =INDEX($C$5:$BV$5,44) | AF16: =INDEX($C$5:$BV$5,43) | AG16: =INDEX($C$5:$BV$5,42) | AH16: =INDEX($C$5:$BV$5,41) | AI16: =INDEX($C$5:$BV$5,40) | AJ16: =INDEX($C$5:$BV$5,39) | AK16: =INDEX($C$5:$BV$5,38) | AL16: =INDEX($C$5:$BV$5,37) | AM16: =INDEX($C$5:$BV$5,36) | AN16: =INDEX($C$5:$BV$5,35) | AO16: =INDEX($C$5:$BV$5,34) | AP16: =INDEX($C$5:$BV$5,33) | AQ16: =INDEX($C$5:$BV$5,32) | AR16: =INDEX($C$5:$BV$5,31) | AS16: =INDEX($C$5:$BV$5,30) | AT16: =INDEX($C$5:$BV$5,29) | AU16: =INDEX($C$5:$BV$5,28) | AV16: =INDEX($C$5:$BV$5,27) | AW16: =INDEX($C$5:$BV$5,26) | AX16: =INDEX($C$5:$BV$5,25) | AY16: =INDEX($C$5:$BV$5,24) | AZ16: =INDEX($C$5:$BV$5,23) | BA16: =INDEX($C$5:$BV$5,22) | BB16: =INDEX($C$5:$BV$5,21) | BC16: =INDEX($C$5:$BV$5,20) | BD16: =INDEX($C$5:$BV$5,19) | BE16: =INDEX($C$5:$BV$5,18) | BF16: =INDEX($C$5:$BV$5,17) | BG16: =INDEX($C$5:$BV$5,16) | BH16: =INDEX($C$5:$BV$5,15) | BI16: =INDEX($C$5:$BV$5,14) | BJ16: =INDEX($C$5:$BV$5,13) | BK16: =INDEX($C$5:$BV$5,12) | BL16: =INDEX($C$5:$BV$5,11) | BM16: =INDEX($C$5:$BV$5,10) | BN16: =INDEX($C$5:$BV$5,9) | BO16: =INDEX($C$5:$BV$5,8) | BP16: =INDEX($C$5:$BV$5,7) | BQ16: =INDEX($C$5:$BV$5,6) | BR16: =INDEX($C$5:$BV$5,5) | BS16: =INDEX($C$5:$BV$5,4) | BT16: =INDEX($C$5:$BV$5,3) | BU16: =INDEX($C$5:$BV$5,2) | BV16: =INDEX($C$5:$BV$5,1)
A17: D_MONTHLY@0 reversed | C17: =INDEX($C$6:$BV$6,72) | D17: =INDEX($C$6:$BV$6,71) | E17: =INDEX($C$6:$BV$6,70) | F17: =INDEX($C$6:$BV$6,69) | G17: =INDEX($C$6:$BV$6,68) | H17: =INDEX($C$6:$BV$6,67) | I17: =INDEX($C$6:$BV$6,66) | J17: =INDEX($C$6:$BV$6,65) | K17: =INDEX($C$6:$BV$6,64) | L17: =INDEX($C$6:$BV$6,63) | M17: =INDEX($C$6:$BV$6,62) | N17: =INDEX($C$6:$BV$6,61) | O17: =INDEX($C$6:$BV$6,60) | P17: =INDEX($C$6:$BV$6,59) | Q17: =INDEX($C$6:$BV$6,58) | R17: =INDEX($C$6:$BV$6,57) | S17: =INDEX($C$6:$BV$6,56) | T17: =INDEX($C$6:$BV$6,55) | U17: =INDEX($C$6:$BV$6,54) | V17: =INDEX($C$6:$BV$6,53) | W17: =INDEX($C$6:$BV$6,52) | X17: =INDEX($C$6:$BV$6,51) | Y17: =INDEX($C$6:$BV$6,50) | Z17: =INDEX($C$6:$BV$6,49) | AA17: =INDEX($C$6:$BV$6,48) | AB17: =INDEX($C$6:$BV$6,47) | AC17: =INDEX($C$6:$BV$6,46) | AD17: =INDEX($C$6:$BV$6,45) | AE17: =INDEX($C$6:$BV$6,44) | AF17: =INDEX($C$6:$BV$6,43) | AG17: =INDEX($C$6:$BV$6,42) | AH17: =INDEX($C$6:$BV$6,41) | AI17: =INDEX($C$6:$BV$6,40) | AJ17: =INDEX($C$6:$BV$6,39) | AK17: =INDEX($C$6:$BV$6,38) | AL17: =INDEX($C$6:$BV$6,37) | AM17: =INDEX($C$6:$BV$6,36) | AN17: =INDEX($C$6:$BV$6,35) | AO17: =INDEX($C$6:$BV$6,34) | AP17: =INDEX($C$6:$BV$6,33) | AQ17: =INDEX($C$6:$BV$6,32) | AR17: =INDEX($C$6:$BV$6,31) | AS17: =INDEX($C$6:$BV$6,30) | AT17: =INDEX($C$6:$BV$6,29) | AU17: =INDEX($C$6:$BV$6,28) | AV17: =INDEX($C$6:$BV$6,27) | AW17: =INDEX($C$6:$BV$6,26) | AX17: =INDEX($C$6:$BV$6,25) | AY17: =INDEX($C$6:$BV$6,24) | AZ17: =INDEX($C$6:$BV$6,23) | BA17: =INDEX($C$6:$BV$6,22) | BB17: =INDEX($C$6:$BV$6,21) | BC17: =INDEX($C$6:$BV$6,20) | BD17: =INDEX($C$6:$BV$6,19) | BE17: =INDEX($C$6:$BV$6,18) | BF17: =INDEX($C$6:$BV$6,17) | BG17: =INDEX($C$6:$BV$6,16) | BH17: =INDEX($C$6:$BV$6,15) | BI17: =INDEX($C$6:$BV$6,14) | BJ17: =INDEX($C$6:$BV$6,13) | BK17: =INDEX($C$6:$BV$6,12) | BL17: =INDEX($C$6:$BV$6,11) | BM17: =INDEX($C$6:$BV$6,10) | BN17: =INDEX($C$6:$BV$6,9) | BO17: =INDEX($C$6:$BV$6,8) | BP17: =INDEX($C$6:$BV$6,7) | BQ17: =INDEX($C$6:$BV$6,6) | BR17: =INDEX($C$6:$BV$6,5) | BS17: =INDEX($C$6:$BV$6,4) | BT17: =INDEX($C$6:$BV$6,3) | BU17: =INDEX($C$6:$BV$6,2) | BV17: =INDEX($C$6:$BV$6,1)
A18: D_ANNUAL@0 reversed | C18: =INDEX($C$7:$BV$7,72) | D18: =INDEX($C$7:$BV$7,71) | E18: =INDEX($C$7:$BV$7,70) | F18: =INDEX($C$7:$BV$7,69) | G18: =INDEX($C$7:$BV$7,68) | H18: =INDEX($C$7:$BV$7,67) | I18: =INDEX($C$7:$BV$7,66) | J18: =INDEX($C$7:$BV$7,65) | K18: =INDEX($C$7:$BV$7,64) | L18: =INDEX($C$7:$BV$7,63) | M18: =INDEX($C$7:$BV$7,62) | N18: =INDEX($C$7:$BV$7,61) | O18: =INDEX($C$7:$BV$7,60) | P18: =INDEX($C$7:$BV$7,59) | Q18: =INDEX($C$7:$BV$7,58) | R18: =INDEX($C$7:$BV$7,57) | S18: =INDEX($C$7:$BV$7,56) | T18: =INDEX($C$7:$BV$7,55) | U18: =INDEX($C$7:$BV$7,54) | V18: =INDEX($C$7:$BV$7,53) | W18: =INDEX($C$7:$BV$7,52) | X18: =INDEX($C$7:$BV$7,51) | Y18: =INDEX($C$7:$BV$7,50) | Z18: =INDEX($C$7:$BV$7,49) | AA18: =INDEX($C$7:$BV$7,48) | AB18: =INDEX($C$7:$BV$7,47) | AC18: =INDEX($C$7:$BV$7,46) | AD18: =INDEX($C$7:$BV$7,45) | AE18: =INDEX($C$7:$BV$7,44) | AF18: =INDEX($C$7:$BV$7,43) | AG18: =INDEX($C$7:$BV$7,42) | AH18: =INDEX($C$7:$BV$7,41) | AI18: =INDEX($C$7:$BV$7,40) | AJ18: =INDEX($C$7:$BV$7,39) | AK18: =INDEX($C$7:$BV$7,38) | AL18: =INDEX($C$7:$BV$7,37) | AM18: =INDEX($C$7:$BV$7,36) | AN18: =INDEX($C$7:$BV$7,35) | AO18: =INDEX($C$7:$BV$7,34) | AP18: =INDEX($C$7:$BV$7,33) | AQ18: =INDEX($C$7:$BV$7,32) | AR18: =INDEX($C$7:$BV$7,31) | AS18: =INDEX($C$7:$BV$7,30) | AT18: =INDEX($C$7:$BV$7,29) | AU18: =INDEX($C$7:$BV$7,28) | AV18: =INDEX($C$7:$BV$7,27) | AW18: =INDEX($C$7:$BV$7,26) | AX18: =INDEX($C$7:$BV$7,25) | AY18: =INDEX($C$7:$BV$7,24) | AZ18: =INDEX($C$7:$BV$7,23) | BA18: =INDEX($C$7:$BV$7,22) | BB18: =INDEX($C$7:$BV$7,21) | BC18: =INDEX($C$7:$BV$7,20) | BD18: =INDEX($C$7:$BV$7,19) | BE18: =INDEX($C$7:$BV$7,18) | BF18: =INDEX($C$7:$BV$7,17) | BG18: =INDEX($C$7:$BV$7,16) | BH18: =INDEX($C$7:$BV$7,15) | BI18: =INDEX($C$7:$BV$7,14) | BJ18: =INDEX($C$7:$BV$7,13) | BK18: =INDEX($C$7:$BV$7,12) | BL18: =INDEX($C$7:$BV$7,11) | BM18: =INDEX($C$7:$BV$7,10) | BN18: =INDEX($C$7:$BV$7,9) | BO18: =INDEX($C$7:$BV$7,8) | BP18: =INDEX($C$7:$BV$7,7) | BQ18: =INDEX($C$7:$BV$7,6) | BR18: =INDEX($C$7:$BV$7,5) | BS18: =INDEX($C$7:$BV$7,4) | BT18: =INDEX($C$7:$BV$7,3) | BU18: =INDEX($C$7:$BV$7,2) | BV18: =INDEX($C$7:$BV$7,1)
A19: S_REACT@0 reversed | C19: =INDEX($C$8:$BV$8,72) | D19: =INDEX($C$8:$BV$8,71) | E19: =INDEX($C$8:$BV$8,70) | F19: =INDEX($C$8:$BV$8,69) | G19: =INDEX($C$8:$BV$8,68) | H19: =INDEX($C$8:$BV$8,67) | I19: =INDEX($C$8:$BV$8,66) | J19: =INDEX($C$8:$BV$8,65) | K19: =INDEX($C$8:$BV$8,64) | L19: =INDEX($C$8:$BV$8,63) | M19: =INDEX($C$8:$BV$8,62) | N19: =INDEX($C$8:$BV$8,61) | O19: =INDEX($C$8:$BV$8,60) | P19: =INDEX($C$8:$BV$8,59) | Q19: =INDEX($C$8:$BV$8,58) | R19: =INDEX($C$8:$BV$8,57) | S19: =INDEX($C$8:$BV$8,56) | T19: =INDEX($C$8:$BV$8,55) | U19: =INDEX($C$8:$BV$8,54) | V19: =INDEX($C$8:$BV$8,53) | W19: =INDEX($C$8:$BV$8,52) | X19: =INDEX($C$8:$BV$8,51) | Y19: =INDEX($C$8:$BV$8,50) | Z19: =INDEX($C$8:$BV$8,49) | AA19: =INDEX($C$8:$BV$8,48) | AB19: =INDEX($C$8:$BV$8,47) | AC19: =INDEX($C$8:$BV$8,46) | AD19: =INDEX($C$8:$BV$8,45) | AE19: =INDEX($C$8:$BV$8,44) | AF19: =INDEX($C$8:$BV$8,43) | AG19: =INDEX($C$8:$BV$8,42) | AH19: =INDEX($C$8:$BV$8,41) | AI19: =INDEX($C$8:$BV$8,40) | AJ19: =INDEX($C$8:$BV$8,39) | AK19: =INDEX($C$8:$BV$8,38) | AL19: =INDEX($C$8:$BV$8,37) | AM19: =INDEX($C$8:$BV$8,36) | AN19: =INDEX($C$8:$BV$8,35) | AO19: =INDEX($C$8:$BV$8,34) | AP19: =INDEX($C$8:$BV$8,33) | AQ19: =INDEX($C$8:$BV$8,32) | AR19: =INDEX($C$8:$BV$8,31) | AS19: =INDEX($C$8:$BV$8,30) | AT19: =INDEX($C$8:$BV$8,29) | AU19: =INDEX($C$8:$BV$8,28) | AV19: =INDEX($C$8:$BV$8,27) | AW19: =INDEX($C$8:$BV$8,26) | AX19: =INDEX($C$8:$BV$8,25) | AY19: =INDEX($C$8:$BV$8,24) | AZ19: =INDEX($C$8:$BV$8,23) | BA19: =INDEX($C$8:$BV$8,22) | BB19: =INDEX($C$8:$BV$8,21) | BC19: =INDEX($C$8:$BV$8,20) | BD19: =INDEX($C$8:$BV$8,19) | BE19: =INDEX($C$8:$BV$8,18) | BF19: =INDEX($C$8:$BV$8,17) | BG19: =INDEX($C$8:$BV$8,16) | BH19: =INDEX($C$8:$BV$8,15) | BI19: =INDEX($C$8:$BV$8,14) | BJ19: =INDEX($C$8:$BV$8,13) | BK19: =INDEX($C$8:$BV$8,12) | BL19: =INDEX($C$8:$BV$8,11) | BM19: =INDEX($C$8:$BV$8,10) | BN19: =INDEX($C$8:$BV$8,9) | BO19: =INDEX($C$8:$BV$8,8) | BP19: =INDEX($C$8:$BV$8,7) | BQ19: =INDEX($C$8:$BV$8,6) | BR19: =INDEX($C$8:$BV$8,5) | BS19: =INDEX($C$8:$BV$8,4) | BT19: =INDEX($C$8:$BV$8,3) | BU19: =INDEX($C$8:$BV$8,2) | BV19: =INDEX($C$8:$BV$8,1)
A20: D_REACT@0 reversed | C20: =INDEX($C$9:$BV$9,72) | D20: =INDEX($C$9:$BV$9,71) | E20: =INDEX($C$9:$BV$9,70) | F20: =INDEX($C$9:$BV$9,69) | G20: =INDEX($C$9:$BV$9,68) | H20: =INDEX($C$9:$BV$9,67) | I20: =INDEX($C$9:$BV$9,66) | J20: =INDEX($C$9:$BV$9,65) | K20: =INDEX($C$9:$BV$9,64) | L20: =INDEX($C$9:$BV$9,63) | M20: =INDEX($C$9:$BV$9,62) | N20: =INDEX($C$9:$BV$9,61) | O20: =INDEX($C$9:$BV$9,60) | P20: =INDEX($C$9:$BV$9,59) | Q20: =INDEX($C$9:$BV$9,58) | R20: =INDEX($C$9:$BV$9,57) | S20: =INDEX($C$9:$BV$9,56) | T20: =INDEX($C$9:$BV$9,55) | U20: =INDEX($C$9:$BV$9,54) | V20: =INDEX($C$9:$BV$9,53) | W20: =INDEX($C$9:$BV$9,52) | X20: =INDEX($C$9:$BV$9,51) | Y20: =INDEX($C$9:$BV$9,50) | Z20: =INDEX($C$9:$BV$9,49) | AA20: =INDEX($C$9:$BV$9,48) | AB20: =INDEX($C$9:$BV$9,47) | AC20: =INDEX($C$9:$BV$9,46) | AD20: =INDEX($C$9:$BV$9,45) | AE20: =INDEX($C$9:$BV$9,44) | AF20: =INDEX($C$9:$BV$9,43) | AG20: =INDEX($C$9:$BV$9,42) | AH20: =INDEX($C$9:$BV$9,41) | AI20: =INDEX($C$9:$BV$9,40) | AJ20: =INDEX($C$9:$BV$9,39) | AK20: =INDEX($C$9:$BV$9,38) | AL20: =INDEX($C$9:$BV$9,37) | AM20: =INDEX($C$9:$BV$9,36) | AN20: =INDEX($C$9:$BV$9,35) | AO20: =INDEX($C$9:$BV$9,34) | AP20: =INDEX($C$9:$BV$9,33) | AQ20: =INDEX($C$9:$BV$9,32) | AR20: =INDEX($C$9:$BV$9,31) | AS20: =INDEX($C$9:$BV$9,30) | AT20: =INDEX($C$9:$BV$9,29) | AU20: =INDEX($C$9:$BV$9,28) | AV20: =INDEX($C$9:$BV$9,27) | AW20: =INDEX($C$9:$BV$9,26) | AX20: =INDEX($C$9:$BV$9,25) | AY20: =INDEX($C$9:$BV$9,24) | AZ20: =INDEX($C$9:$BV$9,23) | BA20: =INDEX($C$9:$BV$9,22) | BB20: =INDEX($C$9:$BV$9,21) | BC20: =INDEX($C$9:$BV$9,20) | BD20: =INDEX($C$9:$BV$9,19) | BE20: =INDEX($C$9:$BV$9,18) | BF20: =INDEX($C$9:$BV$9,17) | BG20: =INDEX($C$9:$BV$9,16) | BH20: =INDEX($C$9:$BV$9,15) | BI20: =INDEX($C$9:$BV$9,14) | BJ20: =INDEX($C$9:$BV$9,13) | BK20: =INDEX($C$9:$BV$9,12) | BL20: =INDEX($C$9:$BV$9,11) | BM20: =INDEX($C$9:$BV$9,10) | BN20: =INDEX($C$9:$BV$9,9) | BO20: =INDEX($C$9:$BV$9,8) | BP20: =INDEX($C$9:$BV$9,7) | BQ20: =INDEX($C$9:$BV$9,6) | BR20: =INDEX($C$9:$BV$9,5) | BS20: =INDEX($C$9:$BV$9,4) | BT20: =INDEX($C$9:$BV$9,3) | BU20: =INDEX($C$9:$BV$9,2) | BV20: =INDEX($C$9:$BV$9,1)
A21: K_REACT@0 reversed | C21: =INDEX($C$10:$BV$10,72) | D21: =INDEX($C$10:$BV$10,71) | E21: =INDEX($C$10:$BV$10,70) | F21: =INDEX($C$10:$BV$10,69) | G21: =INDEX($C$10:$BV$10,68) | H21: =INDEX($C$10:$BV$10,67) | I21: =INDEX($C$10:$BV$10,66) | J21: =INDEX($C$10:$BV$10,65) | K21: =INDEX($C$10:$BV$10,64) | L21: =INDEX($C$10:$BV$10,63) | M21: =INDEX($C$10:$BV$10,62) | N21: =INDEX($C$10:$BV$10,61) | O21: =INDEX($C$10:$BV$10,60) | P21: =INDEX($C$10:$BV$10,59) | Q21: =INDEX($C$10:$BV$10,58) | R21: =INDEX($C$10:$BV$10,57) | S21: =INDEX($C$10:$BV$10,56) | T21: =INDEX($C$10:$BV$10,55) | U21: =INDEX($C$10:$BV$10,54) | V21: =INDEX($C$10:$BV$10,53) | W21: =INDEX($C$10:$BV$10,52) | X21: =INDEX($C$10:$BV$10,51) | Y21: =INDEX($C$10:$BV$10,50) | Z21: =INDEX($C$10:$BV$10,49) | AA21: =INDEX($C$10:$BV$10,48) | AB21: =INDEX($C$10:$BV$10,47) | AC21: =INDEX($C$10:$BV$10,46) | AD21: =INDEX($C$10:$BV$10,45) | AE21: =INDEX($C$10:$BV$10,44) | AF21: =INDEX($C$10:$BV$10,43) | AG21: =INDEX($C$10:$BV$10,42) | AH21: =INDEX($C$10:$BV$10,41) | AI21: =INDEX($C$10:$BV$10,40) | AJ21: =INDEX($C$10:$BV$10,39) | AK21: =INDEX($C$10:$BV$10,38) | AL21: =INDEX($C$10:$BV$10,37) | AM21: =INDEX($C$10:$BV$10,36) | AN21: =INDEX($C$10:$BV$10,35) | AO21: =INDEX($C$10:$BV$10,34) | AP21: =INDEX($C$10:$BV$10,33) | AQ21: =INDEX($C$10:$BV$10,32) | AR21: =INDEX($C$10:$BV$10,31) | AS21: =INDEX($C$10:$BV$10,30) | AT21: =INDEX($C$10:$BV$10,29) | AU21: =INDEX($C$10:$BV$10,28) | AV21: =INDEX($C$10:$BV$10,27) | AW21: =INDEX($C$10:$BV$10,26) | AX21: =INDEX($C$10:$BV$10,25) | AY21: =INDEX($C$10:$BV$10,24) | AZ21: =INDEX($C$10:$BV$10,23) | BA21: =INDEX($C$10:$BV$10,22) | BB21: =INDEX($C$10:$BV$10,21) | BC21: =INDEX($C$10:$BV$10,20) | BD21: =INDEX($C$10:$BV$10,19) | BE21: =INDEX($C$10:$BV$10,18) | BF21: =INDEX($C$10:$BV$10,17) | BG21: =INDEX($C$10:$BV$10,16) | BH21: =INDEX($C$10:$BV$10,15) | BI21: =INDEX($C$10:$BV$10,14) | BJ21: =INDEX($C$10:$BV$10,13) | BK21: =INDEX($C$10:$BV$10,12) | BL21: =INDEX($C$10:$BV$10,11) | BM21: =INDEX($C$10:$BV$10,10) | BN21: =INDEX($C$10:$BV$10,9) | BO21: =INDEX($C$10:$BV$10,8) | BP21: =INDEX($C$10:$BV$10,7) | BQ21: =INDEX($C$10:$BV$10,6) | BR21: =INDEX($C$10:$BV$10,5) | BS21: =INDEX($C$10:$BV$10,4) | BT21: =INDEX($C$10:$BV$10,3) | BU21: =INDEX($C$10:$BV$10,2) | BV21: =INDEX($C$10:$BV$10,1)
A22: S_MONTHLY_Y1@0 reversed | C22: =INDEX($C$11:$BV$11,72) | D22: =INDEX($C$11:$BV$11,71) | E22: =INDEX($C$11:$BV$11,70) | F22: =INDEX($C$11:$BV$11,69) | G22: =INDEX($C$11:$BV$11,68) | H22: =INDEX($C$11:$BV$11,67) | I22: =INDEX($C$11:$BV$11,66) | J22: =INDEX($C$11:$BV$11,65) | K22: =INDEX($C$11:$BV$11,64) | L22: =INDEX($C$11:$BV$11,63) | M22: =INDEX($C$11:$BV$11,62) | N22: =INDEX($C$11:$BV$11,61) | O22: =INDEX($C$11:$BV$11,60) | P22: =INDEX($C$11:$BV$11,59) | Q22: =INDEX($C$11:$BV$11,58) | R22: =INDEX($C$11:$BV$11,57) | S22: =INDEX($C$11:$BV$11,56) | T22: =INDEX($C$11:$BV$11,55) | U22: =INDEX($C$11:$BV$11,54) | V22: =INDEX($C$11:$BV$11,53) | W22: =INDEX($C$11:$BV$11,52) | X22: =INDEX($C$11:$BV$11,51) | Y22: =INDEX($C$11:$BV$11,50) | Z22: =INDEX($C$11:$BV$11,49) | AA22: =INDEX($C$11:$BV$11,48) | AB22: =INDEX($C$11:$BV$11,47) | AC22: =INDEX($C$11:$BV$11,46) | AD22: =INDEX($C$11:$BV$11,45) | AE22: =INDEX($C$11:$BV$11,44) | AF22: =INDEX($C$11:$BV$11,43) | AG22: =INDEX($C$11:$BV$11,42) | AH22: =INDEX($C$11:$BV$11,41) | AI22: =INDEX($C$11:$BV$11,40) | AJ22: =INDEX($C$11:$BV$11,39) | AK22: =INDEX($C$11:$BV$11,38) | AL22: =INDEX($C$11:$BV$11,37) | AM22: =INDEX($C$11:$BV$11,36) | AN22: =INDEX($C$11:$BV$11,35) | AO22: =INDEX($C$11:$BV$11,34) | AP22: =INDEX($C$11:$BV$11,33) | AQ22: =INDEX($C$11:$BV$11,32) | AR22: =INDEX($C$11:$BV$11,31) | AS22: =INDEX($C$11:$BV$11,30) | AT22: =INDEX($C$11:$BV$11,29) | AU22: =INDEX($C$11:$BV$11,28) | AV22: =INDEX($C$11:$BV$11,27) | AW22: =INDEX($C$11:$BV$11,26) | AX22: =INDEX($C$11:$BV$11,25) | AY22: =INDEX($C$11:$BV$11,24) | AZ22: =INDEX($C$11:$BV$11,23) | BA22: =INDEX($C$11:$BV$11,22) | BB22: =INDEX($C$11:$BV$11,21) | BC22: =INDEX($C$11:$BV$11,20) | BD22: =INDEX($C$11:$BV$11,19) | BE22: =INDEX($C$11:$BV$11,18) | BF22: =INDEX($C$11:$BV$11,17) | BG22: =INDEX($C$11:$BV$11,16) | BH22: =INDEX($C$11:$BV$11,15) | BI22: =INDEX($C$11:$BV$11,14) | BJ22: =INDEX($C$11:$BV$11,13) | BK22: =INDEX($C$11:$BV$11,12) | BL22: =INDEX($C$11:$BV$11,11) | BM22: =INDEX($C$11:$BV$11,10) | BN22: =INDEX($C$11:$BV$11,9) | BO22: =INDEX($C$11:$BV$11,8) | BP22: =INDEX($C$11:$BV$11,7) | BQ22: =INDEX($C$11:$BV$11,6) | BR22: =INDEX($C$11:$BV$11,5) | BS22: =INDEX($C$11:$BV$11,4) | BT22: =INDEX($C$11:$BV$11,3) | BU22: =INDEX($C$11:$BV$11,2) | BV22: =INDEX($C$11:$BV$11,1)
A23: S_ANNUAL_Y1@0 reversed | C23: =INDEX($C$12:$BV$12,72) | D23: =INDEX($C$12:$BV$12,71) | E23: =INDEX($C$12:$BV$12,70) | F23: =INDEX($C$12:$BV$12,69) | G23: =INDEX($C$12:$BV$12,68) | H23: =INDEX($C$12:$BV$12,67) | I23: =INDEX($C$12:$BV$12,66) | J23: =INDEX($C$12:$BV$12,65) | K23: =INDEX($C$12:$BV$12,64) | L23: =INDEX($C$12:$BV$12,63) | M23: =INDEX($C$12:$BV$12,62) | N23: =INDEX($C$12:$BV$12,61) | O23: =INDEX($C$12:$BV$12,60) | P23: =INDEX($C$12:$BV$12,59) | Q23: =INDEX($C$12:$BV$12,58) | R23: =INDEX($C$12:$BV$12,57) | S23: =INDEX($C$12:$BV$12,56) | T23: =INDEX($C$12:$BV$12,55) | U23: =INDEX($C$12:$BV$12,54) | V23: =INDEX($C$12:$BV$12,53) | W23: =INDEX($C$12:$BV$12,52) | X23: =INDEX($C$12:$BV$12,51) | Y23: =INDEX($C$12:$BV$12,50) | Z23: =INDEX($C$12:$BV$12,49) | AA23: =INDEX($C$12:$BV$12,48) | AB23: =INDEX($C$12:$BV$12,47) | AC23: =INDEX($C$12:$BV$12,46) | AD23: =INDEX($C$12:$BV$12,45) | AE23: =INDEX($C$12:$BV$12,44) | AF23: =INDEX($C$12:$BV$12,43) | AG23: =INDEX($C$12:$BV$12,42) | AH23: =INDEX($C$12:$BV$12,41) | AI23: =INDEX($C$12:$BV$12,40) | AJ23: =INDEX($C$12:$BV$12,39) | AK23: =INDEX($C$12:$BV$12,38) | AL23: =INDEX($C$12:$BV$12,37) | AM23: =INDEX($C$12:$BV$12,36) | AN23: =INDEX($C$12:$BV$12,35) | AO23: =INDEX($C$12:$BV$12,34) | AP23: =INDEX($C$12:$BV$12,33) | AQ23: =INDEX($C$12:$BV$12,32) | AR23: =INDEX($C$12:$BV$12,31) | AS23: =INDEX($C$12:$BV$12,30) | AT23: =INDEX($C$12:$BV$12,29) | AU23: =INDEX($C$12:$BV$12,28) | AV23: =INDEX($C$12:$BV$12,27) | AW23: =INDEX($C$12:$BV$12,26) | AX23: =INDEX($C$12:$BV$12,25) | AY23: =INDEX($C$12:$BV$12,24) | AZ23: =INDEX($C$12:$BV$12,23) | BA23: =INDEX($C$12:$BV$12,22) | BB23: =INDEX($C$12:$BV$12,21) | BC23: =INDEX($C$12:$BV$12,20) | BD23: =INDEX($C$12:$BV$12,19) | BE23: =INDEX($C$12:$BV$12,18) | BF23: =INDEX($C$12:$BV$12,17) | BG23: =INDEX($C$12:$BV$12,16) | BH23: =INDEX($C$12:$BV$12,15) | BI23: =INDEX($C$12:$BV$12,14) | BJ23: =INDEX($C$12:$BV$12,13) | BK23: =INDEX($C$12:$BV$12,12) | BL23: =INDEX($C$12:$BV$12,11) | BM23: =INDEX($C$12:$BV$12,10) | BN23: =INDEX($C$12:$BV$12,9) | BO23: =INDEX($C$12:$BV$12,8) | BP23: =INDEX($C$12:$BV$12,7) | BQ23: =INDEX($C$12:$BV$12,6) | BR23: =INDEX($C$12:$BV$12,5) | BS23: =INDEX($C$12:$BV$12,4) | BT23: =INDEX($C$12:$BV$12,3) | BU23: =INDEX($C$12:$BV$12,2) | BV23: =INDEX($C$12:$BV$12,1)
A24: S_REACT_Y1@0 reversed | C24: =INDEX($C$13:$BV$13,72) | D24: =INDEX($C$13:$BV$13,71) | E24: =INDEX($C$13:$BV$13,70) | F24: =INDEX($C$13:$BV$13,69) | G24: =INDEX($C$13:$BV$13,68) | H24: =INDEX($C$13:$BV$13,67) | I24: =INDEX($C$13:$BV$13,66) | J24: =INDEX($C$13:$BV$13,65) | K24: =INDEX($C$13:$BV$13,64) | L24: =INDEX($C$13:$BV$13,63) | M24: =INDEX($C$13:$BV$13,62) | N24: =INDEX($C$13:$BV$13,61) | O24: =INDEX($C$13:$BV$13,60) | P24: =INDEX($C$13:$BV$13,59) | Q24: =INDEX($C$13:$BV$13,58) | R24: =INDEX($C$13:$BV$13,57) | S24: =INDEX($C$13:$BV$13,56) | T24: =INDEX($C$13:$BV$13,55) | U24: =INDEX($C$13:$BV$13,54) | V24: =INDEX($C$13:$BV$13,53) | W24: =INDEX($C$13:$BV$13,52) | X24: =INDEX($C$13:$BV$13,51) | Y24: =INDEX($C$13:$BV$13,50) | Z24: =INDEX($C$13:$BV$13,49) | AA24: =INDEX($C$13:$BV$13,48) | AB24: =INDEX($C$13:$BV$13,47) | AC24: =INDEX($C$13:$BV$13,46) | AD24: =INDEX($C$13:$BV$13,45) | AE24: =INDEX($C$13:$BV$13,44) | AF24: =INDEX($C$13:$BV$13,43) | AG24: =INDEX($C$13:$BV$13,42) | AH24: =INDEX($C$13:$BV$13,41) | AI24: =INDEX($C$13:$BV$13,40) | AJ24: =INDEX($C$13:$BV$13,39) | AK24: =INDEX($C$13:$BV$13,38) | AL24: =INDEX($C$13:$BV$13,37) | AM24: =INDEX($C$13:$BV$13,36) | AN24: =INDEX($C$13:$BV$13,35) | AO24: =INDEX($C$13:$BV$13,34) | AP24: =INDEX($C$13:$BV$13,33) | AQ24: =INDEX($C$13:$BV$13,32) | AR24: =INDEX($C$13:$BV$13,31) | AS24: =INDEX($C$13:$BV$13,30) | AT24: =INDEX($C$13:$BV$13,29) | AU24: =INDEX($C$13:$BV$13,28) | AV24: =INDEX($C$13:$BV$13,27) | AW24: =INDEX($C$13:$BV$13,26) | AX24: =INDEX($C$13:$BV$13,25) | AY24: =INDEX($C$13:$BV$13,24) | AZ24: =INDEX($C$13:$BV$13,23) | BA24: =INDEX($C$13:$BV$13,22) | BB24: =INDEX($C$13:$BV$13,21) | BC24: =INDEX($C$13:$BV$13,20) | BD24: =INDEX($C$13:$BV$13,19) | BE24: =INDEX($C$13:$BV$13,18) | BF24: =INDEX($C$13:$BV$13,17) | BG24: =INDEX($C$13:$BV$13,16) | BH24: =INDEX($C$13:$BV$13,15) | BI24: =INDEX($C$13:$BV$13,14) | BJ24: =INDEX($C$13:$BV$13,13) | BK24: =INDEX($C$13:$BV$13,12) | BL24: =INDEX($C$13:$BV$13,11) | BM24: =INDEX($C$13:$BV$13,10) | BN24: =INDEX($C$13:$BV$13,9) | BO24: =INDEX($C$13:$BV$13,8) | BP24: =INDEX($C$13:$BV$13,7) | BQ24: =INDEX($C$13:$BV$13,6) | BR24: =INDEX($C$13:$BV$13,5) | BS24: =INDEX($C$13:$BV$13,4) | BT24: =INDEX($C$13:$BV$13,3) | BU24: =INDEX($C$13:$BV$13,2) | BV24: =INDEX($C$13:$BV$13,1)
A26: @1: forecast
A27: S_MONTHLY@1 | C27: =1 | D27: =C27*(1-IF(D$1=1,Params!$B$33,IF(D$1=2,Params!$B$35,IF(D$1=3,Params!$B$37,Params!$B$39)))) | E27: =D27*(1-IF(E$1=1,Params!$B$33,IF(E$1=2,Params!$B$35,IF(E$1=3,Params!$B$37,Params!$B$39)))) | F27: =E27*(1-IF(F$1=1,Params!$B$33,IF(F$1=2,Params!$B$35,IF(F$1=3,Params!$B$37,Params!$B$39)))) | G27: =F27*(1-IF(G$1=1,Params!$B$33,IF(G$1=2,Params!$B$35,IF(G$1=3,Params!$B$37,Params!$B$39)))) | H27: =G27*(1-IF(H$1=1,Params!$B$33,IF(H$1=2,Params!$B$35,IF(H$1=3,Params!$B$37,Params!$B$39)))) | I27: =H27*(1-IF(I$1=1,Params!$B$33,IF(I$1=2,Params!$B$35,IF(I$1=3,Params!$B$37,Params!$B$39)))) | J27: =I27*(1-IF(J$1=1,Params!$B$33,IF(J$1=2,Params!$B$35,IF(J$1=3,Params!$B$37,Params!$B$39)))) | K27: =J27*(1-IF(K$1=1,Params!$B$33,IF(K$1=2,Params!$B$35,IF(K$1=3,Params!$B$37,Params!$B$39)))) | ... BV27: =BU27*(1-IF(BV$1=1,Params!$B$33,IF(BV$1=2,Params!$B$35,IF(BV$1=3,Params!$B$37,Params!$B$39))))
A28: S_ANNUAL@1 | C28: =IF(C$1<12,1,Params!$B$41*Params!$B$43^(INT(C$1/12)-1)) | D28: =IF(D$1<12,1,Params!$B$41*Params!$B$43^(INT(D$1/12)-1)) | E28: =IF(E$1<12,1,Params!$B$41*Params!$B$43^(INT(E$1/12)-1)) | F28: =IF(F$1<12,1,Params!$B$41*Params!$B$43^(INT(F$1/12)-1)) | G28: =IF(G$1<12,1,Params!$B$41*Params!$B$43^(INT(G$1/12)-1)) | H28: =IF(H$1<12,1,Params!$B$41*Params!$B$43^(INT(H$1/12)-1)) | I28: =IF(I$1<12,1,Params!$B$41*Params!$B$43^(INT(I$1/12)-1)) | J28: =IF(J$1<12,1,Params!$B$41*Params!$B$43^(INT(J$1/12)-1)) | ... BV28: =IF(BV$1<12,1,Params!$B$41*Params!$B$43^(INT(BV$1/12)-1))
A29: D_MONTHLY@1 | C29: =0 | D29: =C27-D27 | E29: =D27-E27 | F29: =E27-F27 | G29: =F27-G27 | H29: =G27-H27 | I29: =H27-I27 | J29: =I27-J27 | K29: =J27-K27 | ... BV29: =BU27-BV27
A30: D_ANNUAL@1 | C30: =0 | D30: =C28-D28 | E30: =D28-E28 | F30: =E28-F28 | G30: =F28-G28 | H30: =G28-H28 | I30: =H28-I28 | J30: =I28-J28 | K30: =J28-K28 | ... BV30: =BU28-BV28
A31: S_REACT@1 | C31: =(1-Params!$B$49)^C$1 | D31: =(1-Params!$B$49)^D$1 | E31: =(1-Params!$B$49)^E$1 | F31: =(1-Params!$B$49)^F$1 | G31: =(1-Params!$B$49)^G$1 | H31: =(1-Params!$B$49)^H$1 | I31: =(1-Params!$B$49)^I$1 | J31: =(1-Params!$B$49)^J$1 | ... BV31: =(1-Params!$B$49)^BV$1
A32: D_REACT@1 | C32: =0 | D32: =C31-D31 | E32: =D31-E31 | F32: =E31-F31 | G32: =F31-G31 | H32: =G31-H31 | I32: =H31-I31 | J32: =I31-J31 | K32: =J31-K31 | ... BV32: =BU31-BV31
A33: K_REACT@1 | C33: =IF(AND(C$1>=1,C$1<=Params!$B$47),Params!$B$45*(1-Params!$B$45)^(C$1-1),0) | D33: =IF(AND(D$1>=1,D$1<=Params!$B$47),Params!$B$45*(1-Params!$B$45)^(D$1-1),0) | E33: =IF(AND(E$1>=1,E$1<=Params!$B$47),Params!$B$45*(1-Params!$B$45)^(E$1-1),0) | F33: =IF(AND(F$1>=1,F$1<=Params!$B$47),Params!$B$45*(1-Params!$B$45)^(F$1-1),0) | G33: =IF(AND(G$1>=1,G$1<=Params!$B$47),Params!$B$45*(1-Params!$B$45)^(G$1-1),0) | H33: =IF(AND(H$1>=1,H$1<=Params!$B$47),Params!$B$45*(1-Params!$B$45)^(H$1-1),0) | I33: =IF(AND(I$1>=1,I$1<=Params!$B$47),Params!$B$45*(1-Params!$B$45)^(I$1-1),0) | J33: =IF(AND(J$1>=1,J$1<=Params!$B$47),Params!$B$45*(1-Params!$B$45)^(J$1-1),0) | ... BV33: =IF(AND(BV$1>=1,BV$1<=Params!$B$47),Params!$B$45*(1-Params!$B$45)^(BV$1-1),0)
A34: S_MONTHLY_Y1@1 | C34: =IF(C$1<12,C27,0) | D34: =IF(D$1<12,D27,0) | E34: =IF(E$1<12,E27,0) | F34: =IF(F$1<12,F27,0) | G34: =IF(G$1<12,G27,0) | H34: =IF(H$1<12,H27,0) | I34: =IF(I$1<12,I27,0) | J34: =IF(J$1<12,J27,0) | ... BV34: =IF(BV$1<12,BV27,0)
A35: S_ANNUAL_Y1@1 | C35: =IF(C$1<12,C28,0) | D35: =IF(D$1<12,D28,0) | E35: =IF(E$1<12,E28,0) | F35: =IF(F$1<12,F28,0) | G35: =IF(G$1<12,G28,0) | H35: =IF(H$1<12,H28,0) | I35: =IF(I$1<12,I28,0) | J35: =IF(J$1<12,J28,0) | ... BV35: =IF(BV$1<12,BV28,0)
A36: S_REACT_Y1@1 | C36: =IF(C$1<12,C31,0) | D36: =IF(D$1<12,D31,0) | E36: =IF(E$1<12,E31,0) | F36: =IF(F$1<12,F31,0) | G36: =IF(G$1<12,G31,0) | H36: =IF(H$1<12,H31,0) | I36: =IF(I$1<12,I31,0) | J36: =IF(J$1<12,J31,0) | ... BV36: =IF(BV$1<12,BV31,0)
A38: S_MONTHLY@1 reversed | C38: =INDEX($C$27:$BV$27,72) | D38: =INDEX($C$27:$BV$27,71) | E38: =INDEX($C$27:$BV$27,70) | F38: =INDEX($C$27:$BV$27,69) | G38: =INDEX($C$27:$BV$27,68) | H38: =INDEX($C$27:$BV$27,67) | I38: =INDEX($C$27:$BV$27,66) | J38: =INDEX($C$27:$BV$27,65) | K38: =INDEX($C$27:$BV$27,64) | L38: =INDEX($C$27:$BV$27,63) | M38: =INDEX($C$27:$BV$27,62) | N38: =INDEX($C$27:$BV$27,61) | O38: =INDEX($C$27:$BV$27,60) | P38: =INDEX($C$27:$BV$27,59) | Q38: =INDEX($C$27:$BV$27,58) | R38: =INDEX($C$27:$BV$27,57) | S38: =INDEX($C$27:$BV$27,56) | T38: =INDEX($C$27:$BV$27,55) | U38: =INDEX($C$27:$BV$27,54) | V38: =INDEX($C$27:$BV$27,53) | W38: =INDEX($C$27:$BV$27,52) | X38: =INDEX($C$27:$BV$27,51) | Y38: =INDEX($C$27:$BV$27,50) | Z38: =INDEX($C$27:$BV$27,49) | AA38: =INDEX($C$27:$BV$27,48) | AB38: =INDEX($C$27:$BV$27,47) | AC38: =INDEX($C$27:$BV$27,46) | AD38: =INDEX($C$27:$BV$27,45) | AE38: =INDEX($C$27:$BV$27,44) | AF38: =INDEX($C$27:$BV$27,43) | AG38: =INDEX($C$27:$BV$27,42) | AH38: =INDEX($C$27:$BV$27,41) | AI38: =INDEX($C$27:$BV$27,40) | AJ38: =INDEX($C$27:$BV$27,39) | AK38: =INDEX($C$27:$BV$27,38) | AL38: =INDEX($C$27:$BV$27,37) | AM38: =INDEX($C$27:$BV$27,36) | AN38: =INDEX($C$27:$BV$27,35) | AO38: =INDEX($C$27:$BV$27,34) | AP38: =INDEX($C$27:$BV$27,33) | AQ38: =INDEX($C$27:$BV$27,32) | AR38: =INDEX($C$27:$BV$27,31) | AS38: =INDEX($C$27:$BV$27,30) | AT38: =INDEX($C$27:$BV$27,29) | AU38: =INDEX($C$27:$BV$27,28) | AV38: =INDEX($C$27:$BV$27,27) | AW38: =INDEX($C$27:$BV$27,26) | AX38: =INDEX($C$27:$BV$27,25) | AY38: =INDEX($C$27:$BV$27,24) | AZ38: =INDEX($C$27:$BV$27,23) | BA38: =INDEX($C$27:$BV$27,22) | BB38: =INDEX($C$27:$BV$27,21) | BC38: =INDEX($C$27:$BV$27,20) | BD38: =INDEX($C$27:$BV$27,19) | BE38: =INDEX($C$27:$BV$27,18) | BF38: =INDEX($C$27:$BV$27,17) | BG38: =INDEX($C$27:$BV$27,16) | BH38: =INDEX($C$27:$BV$27,15) | BI38: =INDEX($C$27:$BV$27,14) | BJ38: =INDEX($C$27:$BV$27,13) | BK38: =INDEX($C$27:$BV$27,12) | BL38: =INDEX($C$27:$BV$27,11) | BM38: =INDEX($C$27:$BV$27,10) | BN38: =INDEX($C$27:$BV$27,9) | BO38: =INDEX($C$27:$BV$27,8) | BP38: =INDEX($C$27:$BV$27,7) | BQ38: =INDEX($C$27:$BV$27,6) | BR38: =INDEX($C$27:$BV$27,5) | BS38: =INDEX($C$27:$BV$27,4) | BT38: =INDEX($C$27:$BV$27,3) | BU38: =INDEX($C$27:$BV$27,2) | BV38: =INDEX($C$27:$BV$27,1)
A39: S_ANNUAL@1 reversed | C39: =INDEX($C$28:$BV$28,72) | D39: =INDEX($C$28:$BV$28,71) | E39: =INDEX($C$28:$BV$28,70) | F39: =INDEX($C$28:$BV$28,69) | G39: =INDEX($C$28:$BV$28,68) | H39: =INDEX($C$28:$BV$28,67) | I39: =INDEX($C$28:$BV$28,66) | J39: =INDEX($C$28:$BV$28,65) | K39: =INDEX($C$28:$BV$28,64) | L39: =INDEX($C$28:$BV$28,63) | M39: =INDEX($C$28:$BV$28,62) | N39: =INDEX($C$28:$BV$28,61) | O39: =INDEX($C$28:$BV$28,60) | P39: =INDEX($C$28:$BV$28,59) | Q39: =INDEX($C$28:$BV$28,58) | R39: =INDEX($C$28:$BV$28,57) | S39: =INDEX($C$28:$BV$28,56) | T39: =INDEX($C$28:$BV$28,55) | U39: =INDEX($C$28:$BV$28,54) | V39: =INDEX($C$28:$BV$28,53) | W39: =INDEX($C$28:$BV$28,52) | X39: =INDEX($C$28:$BV$28,51) | Y39: =INDEX($C$28:$BV$28,50) | Z39: =INDEX($C$28:$BV$28,49) | AA39: =INDEX($C$28:$BV$28,48) | AB39: =INDEX($C$28:$BV$28,47) | AC39: =INDEX($C$28:$BV$28,46) | AD39: =INDEX($C$28:$BV$28,45) | AE39: =INDEX($C$28:$BV$28,44) | AF39: =INDEX($C$28:$BV$28,43) | AG39: =INDEX($C$28:$BV$28,42) | AH39: =INDEX($C$28:$BV$28,41) | AI39: =INDEX($C$28:$BV$28,40) | AJ39: =INDEX($C$28:$BV$28,39) | AK39: =INDEX($C$28:$BV$28,38) | AL39: =INDEX($C$28:$BV$28,37) | AM39: =INDEX($C$28:$BV$28,36) | AN39: =INDEX($C$28:$BV$28,35) | AO39: =INDEX($C$28:$BV$28,34) | AP39: =INDEX($C$28:$BV$28,33) | AQ39: =INDEX($C$28:$BV$28,32) | AR39: =INDEX($C$28:$BV$28,31) | AS39: =INDEX($C$28:$BV$28,30) | AT39: =INDEX($C$28:$BV$28,29) | AU39: =INDEX($C$28:$BV$28,28) | AV39: =INDEX($C$28:$BV$28,27) | AW39: =INDEX($C$28:$BV$28,26) | AX39: =INDEX($C$28:$BV$28,25) | AY39: =INDEX($C$28:$BV$28,24) | AZ39: =INDEX($C$28:$BV$28,23) | BA39: =INDEX($C$28:$BV$28,22) | BB39: =INDEX($C$28:$BV$28,21) | BC39: =INDEX($C$28:$BV$28,20) | BD39: =INDEX($C$28:$BV$28,19) | BE39: =INDEX($C$28:$BV$28,18) | BF39: =INDEX($C$28:$BV$28,17) | BG39: =INDEX($C$28:$BV$28,16) | BH39: =INDEX($C$28:$BV$28,15) | BI39: =INDEX($C$28:$BV$28,14) | BJ39: =INDEX($C$28:$BV$28,13) | BK39: =INDEX($C$28:$BV$28,12) | BL39: =INDEX($C$28:$BV$28,11) | BM39: =INDEX($C$28:$BV$28,10) | BN39: =INDEX($C$28:$BV$28,9) | BO39: =INDEX($C$28:$BV$28,8) | BP39: =INDEX($C$28:$BV$28,7) | BQ39: =INDEX($C$28:$BV$28,6) | BR39: =INDEX($C$28:$BV$28,5) | BS39: =INDEX($C$28:$BV$28,4) | BT39: =INDEX($C$28:$BV$28,3) | BU39: =INDEX($C$28:$BV$28,2) | BV39: =INDEX($C$28:$BV$28,1)
A40: D_MONTHLY@1 reversed | C40: =INDEX($C$29:$BV$29,72) | D40: =INDEX($C$29:$BV$29,71) | E40: =INDEX($C$29:$BV$29,70) | F40: =INDEX($C$29:$BV$29,69) | G40: =INDEX($C$29:$BV$29,68) | H40: =INDEX($C$29:$BV$29,67) | I40: =INDEX($C$29:$BV$29,66) | J40: =INDEX($C$29:$BV$29,65) | K40: =INDEX($C$29:$BV$29,64) | L40: =INDEX($C$29:$BV$29,63) | M40: =INDEX($C$29:$BV$29,62) | N40: =INDEX($C$29:$BV$29,61) | O40: =INDEX($C$29:$BV$29,60) | P40: =INDEX($C$29:$BV$29,59) | Q40: =INDEX($C$29:$BV$29,58) | R40: =INDEX($C$29:$BV$29,57) | S40: =INDEX($C$29:$BV$29,56) | T40: =INDEX($C$29:$BV$29,55) | U40: =INDEX($C$29:$BV$29,54) | V40: =INDEX($C$29:$BV$29,53) | W40: =INDEX($C$29:$BV$29,52) | X40: =INDEX($C$29:$BV$29,51) | Y40: =INDEX($C$29:$BV$29,50) | Z40: =INDEX($C$29:$BV$29,49) | AA40: =INDEX($C$29:$BV$29,48) | AB40: =INDEX($C$29:$BV$29,47) | AC40: =INDEX($C$29:$BV$29,46) | AD40: =INDEX($C$29:$BV$29,45) | AE40: =INDEX($C$29:$BV$29,44) | AF40: =INDEX($C$29:$BV$29,43) | AG40: =INDEX($C$29:$BV$29,42) | AH40: =INDEX($C$29:$BV$29,41) | AI40: =INDEX($C$29:$BV$29,40) | AJ40: =INDEX($C$29:$BV$29,39) | AK40: =INDEX($C$29:$BV$29,38) | AL40: =INDEX($C$29:$BV$29,37) | AM40: =INDEX($C$29:$BV$29,36) | AN40: =INDEX($C$29:$BV$29,35) | AO40: =INDEX($C$29:$BV$29,34) | AP40: =INDEX($C$29:$BV$29,33) | AQ40: =INDEX($C$29:$BV$29,32) | AR40: =INDEX($C$29:$BV$29,31) | AS40: =INDEX($C$29:$BV$29,30) | AT40: =INDEX($C$29:$BV$29,29) | AU40: =INDEX($C$29:$BV$29,28) | AV40: =INDEX($C$29:$BV$29,27) | AW40: =INDEX($C$29:$BV$29,26) | AX40: =INDEX($C$29:$BV$29,25) | AY40: =INDEX($C$29:$BV$29,24) | AZ40: =INDEX($C$29:$BV$29,23) | BA40: =INDEX($C$29:$BV$29,22) | BB40: =INDEX($C$29:$BV$29,21) | BC40: =INDEX($C$29:$BV$29,20) | BD40: =INDEX($C$29:$BV$29,19) | BE40: =INDEX($C$29:$BV$29,18) | BF40: =INDEX($C$29:$BV$29,17) | BG40: =INDEX($C$29:$BV$29,16) | BH40: =INDEX($C$29:$BV$29,15) | BI40: =INDEX($C$29:$BV$29,14) | BJ40: =INDEX($C$29:$BV$29,13) | BK40: =INDEX($C$29:$BV$29,12) | BL40: =INDEX($C$29:$BV$29,11) | BM40: =INDEX($C$29:$BV$29,10) | BN40: =INDEX($C$29:$BV$29,9) | BO40: =INDEX($C$29:$BV$29,8) | BP40: =INDEX($C$29:$BV$29,7) | BQ40: =INDEX($C$29:$BV$29,6) | BR40: =INDEX($C$29:$BV$29,5) | BS40: =INDEX($C$29:$BV$29,4) | BT40: =INDEX($C$29:$BV$29,3) | BU40: =INDEX($C$29:$BV$29,2) | BV40: =INDEX($C$29:$BV$29,1)
A41: D_ANNUAL@1 reversed | C41: =INDEX($C$30:$BV$30,72) | D41: =INDEX($C$30:$BV$30,71) | E41: =INDEX($C$30:$BV$30,70) | F41: =INDEX($C$30:$BV$30,69) | G41: =INDEX($C$30:$BV$30,68) | H41: =INDEX($C$30:$BV$30,67) | I41: =INDEX($C$30:$BV$30,66) | J41: =INDEX($C$30:$BV$30,65) | K41: =INDEX($C$30:$BV$30,64) | L41: =INDEX($C$30:$BV$30,63) | M41: =INDEX($C$30:$BV$30,62) | N41: =INDEX($C$30:$BV$30,61) | O41: =INDEX($C$30:$BV$30,60) | P41: =INDEX($C$30:$BV$30,59) | Q41: =INDEX($C$30:$BV$30,58) | R41: =INDEX($C$30:$BV$30,57) | S41: =INDEX($C$30:$BV$30,56) | T41: =INDEX($C$30:$BV$30,55) | U41: =INDEX($C$30:$BV$30,54) | V41: =INDEX($C$30:$BV$30,53) | W41: =INDEX($C$30:$BV$30,52) | X41: =INDEX($C$30:$BV$30,51) | Y41: =INDEX($C$30:$BV$30,50) | Z41: =INDEX($C$30:$BV$30,49) | AA41: =INDEX($C$30:$BV$30,48) | AB41: =INDEX($C$30:$BV$30,47) | AC41: =INDEX($C$30:$BV$30,46) | AD41: =INDEX($C$30:$BV$30,45) | AE41: =INDEX($C$30:$BV$30,44) | AF41: =INDEX($C$30:$BV$30,43) | AG41: =INDEX($C$30:$BV$30,42) | AH41: =INDEX($C$30:$BV$30,41) | AI41: =INDEX($C$30:$BV$30,40) | AJ41: =INDEX($C$30:$BV$30,39) | AK41: =INDEX($C$30:$BV$30,38) | AL41: =INDEX($C$30:$BV$30,37) | AM41: =INDEX($C$30:$BV$30,36) | AN41: =INDEX($C$30:$BV$30,35) | AO41: =INDEX($C$30:$BV$30,34) | AP41: =INDEX($C$30:$BV$30,33) | AQ41: =INDEX($C$30:$BV$30,32) | AR41: =INDEX($C$30:$BV$30,31) | AS41: =INDEX($C$30:$BV$30,30) | AT41: =INDEX($C$30:$BV$30,29) | AU41: =INDEX($C$30:$BV$30,28) | AV41: =INDEX($C$30:$BV$30,27) | AW41: =INDEX($C$30:$BV$30,26) | AX41: =INDEX($C$30:$BV$30,25) | AY41: =INDEX($C$30:$BV$30,24) | AZ41: =INDEX($C$30:$BV$30,23) | BA41: =INDEX($C$30:$BV$30,22) | BB41: =INDEX($C$30:$BV$30,21) | BC41: =INDEX($C$30:$BV$30,20) | BD41: =INDEX($C$30:$BV$30,19) | BE41: =INDEX($C$30:$BV$30,18) | BF41: =INDEX($C$30:$BV$30,17) | BG41: =INDEX($C$30:$BV$30,16) | BH41: =INDEX($C$30:$BV$30,15) | BI41: =INDEX($C$30:$BV$30,14) | BJ41: =INDEX($C$30:$BV$30,13) | BK41: =INDEX($C$30:$BV$30,12) | BL41: =INDEX($C$30:$BV$30,11) | BM41: =INDEX($C$30:$BV$30,10) | BN41: =INDEX($C$30:$BV$30,9) | BO41: =INDEX($C$30:$BV$30,8) | BP41: =INDEX($C$30:$BV$30,7) | BQ41: =INDEX($C$30:$BV$30,6) | BR41: =INDEX($C$30:$BV$30,5) | BS41: =INDEX($C$30:$BV$30,4) | BT41: =INDEX($C$30:$BV$30,3) | BU41: =INDEX($C$30:$BV$30,2) | BV41: =INDEX($C$30:$BV$30,1)
A42: S_REACT@1 reversed | C42: =INDEX($C$31:$BV$31,72) | D42: =INDEX($C$31:$BV$31,71) | E42: =INDEX($C$31:$BV$31,70) | F42: =INDEX($C$31:$BV$31,69) | G42: =INDEX($C$31:$BV$31,68) | H42: =INDEX($C$31:$BV$31,67) | I42: =INDEX($C$31:$BV$31,66) | J42: =INDEX($C$31:$BV$31,65) | K42: =INDEX($C$31:$BV$31,64) | L42: =INDEX($C$31:$BV$31,63) | M42: =INDEX($C$31:$BV$31,62) | N42: =INDEX($C$31:$BV$31,61) | O42: =INDEX($C$31:$BV$31,60) | P42: =INDEX($C$31:$BV$31,59) | Q42: =INDEX($C$31:$BV$31,58) | R42: =INDEX($C$31:$BV$31,57) | S42: =INDEX($C$31:$BV$31,56) | T42: =INDEX($C$31:$BV$31,55) | U42: =INDEX($C$31:$BV$31,54) | V42: =INDEX($C$31:$BV$31,53) | W42: =INDEX($C$31:$BV$31,52) | X42: =INDEX($C$31:$BV$31,51) | Y42: =INDEX($C$31:$BV$31,50) | Z42: =INDEX($C$31:$BV$31,49) | AA42: =INDEX($C$31:$BV$31,48) | AB42: =INDEX($C$31:$BV$31,47) | AC42: =INDEX($C$31:$BV$31,46) | AD42: =INDEX($C$31:$BV$31,45) | AE42: =INDEX($C$31:$BV$31,44) | AF42: =INDEX($C$31:$BV$31,43) | AG42: =INDEX($C$31:$BV$31,42) | AH42: =INDEX($C$31:$BV$31,41) | AI42: =INDEX($C$31:$BV$31,40) | AJ42: =INDEX($C$31:$BV$31,39) | AK42: =INDEX($C$31:$BV$31,38) | AL42: =INDEX($C$31:$BV$31,37) | AM42: =INDEX($C$31:$BV$31,36) | AN42: =INDEX($C$31:$BV$31,35) | AO42: =INDEX($C$31:$BV$31,34) | AP42: =INDEX($C$31:$BV$31,33) | AQ42: =INDEX($C$31:$BV$31,32) | AR42: =INDEX($C$31:$BV$31,31) | AS42: =INDEX($C$31:$BV$31,30) | AT42: =INDEX($C$31:$BV$31,29) | AU42: =INDEX($C$31:$BV$31,28) | AV42: =INDEX($C$31:$BV$31,27) | AW42: =INDEX($C$31:$BV$31,26) | AX42: =INDEX($C$31:$BV$31,25) | AY42: =INDEX($C$31:$BV$31,24) | AZ42: =INDEX($C$31:$BV$31,23) | BA42: =INDEX($C$31:$BV$31,22) | BB42: =INDEX($C$31:$BV$31,21) | BC42: =INDEX($C$31:$BV$31,20) | BD42: =INDEX($C$31:$BV$31,19) | BE42: =INDEX($C$31:$BV$31,18) | BF42: =INDEX($C$31:$BV$31,17) | BG42: =INDEX($C$31:$BV$31,16) | BH42: =INDEX($C$31:$BV$31,15) | BI42: =INDEX($C$31:$BV$31,14) | BJ42: =INDEX($C$31:$BV$31,13) | BK42: =INDEX($C$31:$BV$31,12) | BL42: =INDEX($C$31:$BV$31,11) | BM42: =INDEX($C$31:$BV$31,10) | BN42: =INDEX($C$31:$BV$31,9) | BO42: =INDEX($C$31:$BV$31,8) | BP42: =INDEX($C$31:$BV$31,7) | BQ42: =INDEX($C$31:$BV$31,6) | BR42: =INDEX($C$31:$BV$31,5) | BS42: =INDEX($C$31:$BV$31,4) | BT42: =INDEX($C$31:$BV$31,3) | BU42: =INDEX($C$31:$BV$31,2) | BV42: =INDEX($C$31:$BV$31,1)
A43: D_REACT@1 reversed | C43: =INDEX($C$32:$BV$32,72) | D43: =INDEX($C$32:$BV$32,71) | E43: =INDEX($C$32:$BV$32,70) | F43: =INDEX($C$32:$BV$32,69) | G43: =INDEX($C$32:$BV$32,68) | H43: =INDEX($C$32:$BV$32,67) | I43: =INDEX($C$32:$BV$32,66) | J43: =INDEX($C$32:$BV$32,65) | K43: =INDEX($C$32:$BV$32,64) | L43: =INDEX($C$32:$BV$32,63) | M43: =INDEX($C$32:$BV$32,62) | N43: =INDEX($C$32:$BV$32,61) | O43: =INDEX($C$32:$BV$32,60) | P43: =INDEX($C$32:$BV$32,59) | Q43: =INDEX($C$32:$BV$32,58) | R43: =INDEX($C$32:$BV$32,57) | S43: =INDEX($C$32:$BV$32,56) | T43: =INDEX($C$32:$BV$32,55) | U43: =INDEX($C$32:$BV$32,54) | V43: =INDEX($C$32:$BV$32,53) | W43: =INDEX($C$32:$BV$32,52) | X43: =INDEX($C$32:$BV$32,51) | Y43: =INDEX($C$32:$BV$32,50) | Z43: =INDEX($C$32:$BV$32,49) | AA43: =INDEX($C$32:$BV$32,48) | AB43: =INDEX($C$32:$BV$32,47) | AC43: =INDEX($C$32:$BV$32,46) | AD43: =INDEX($C$32:$BV$32,45) | AE43: =INDEX($C$32:$BV$32,44) | AF43: =INDEX($C$32:$BV$32,43) | AG43: =INDEX($C$32:$BV$32,42) | AH43: =INDEX($C$32:$BV$32,41) | AI43: =INDEX($C$32:$BV$32,40) | AJ43: =INDEX($C$32:$BV$32,39) | AK43: =INDEX($C$32:$BV$32,38) | AL43: =INDEX($C$32:$BV$32,37) | AM43: =INDEX($C$32:$BV$32,36) | AN43: =INDEX($C$32:$BV$32,35) | AO43: =INDEX($C$32:$BV$32,34) | AP43: =INDEX($C$32:$BV$32,33) | AQ43: =INDEX($C$32:$BV$32,32) | AR43: =INDEX($C$32:$BV$32,31) | AS43: =INDEX($C$32:$BV$32,30) | AT43: =INDEX($C$32:$BV$32,29) | AU43: =INDEX($C$32:$BV$32,28) | AV43: =INDEX($C$32:$BV$32,27) | AW43: =INDEX($C$32:$BV$32,26) | AX43: =INDEX($C$32:$BV$32,25) | AY43: =INDEX($C$32:$BV$32,24) | AZ43: =INDEX($C$32:$BV$32,23) | BA43: =INDEX($C$32:$BV$32,22) | BB43: =INDEX($C$32:$BV$32,21) | BC43: =INDEX($C$32:$BV$32,20) | BD43: =INDEX($C$32:$BV$32,19) | BE43: =INDEX($C$32:$BV$32,18) | BF43: =INDEX($C$32:$BV$32,17) | BG43: =INDEX($C$32:$BV$32,16) | BH43: =INDEX($C$32:$BV$32,15) | BI43: =INDEX($C$32:$BV$32,14) | BJ43: =INDEX($C$32:$BV$32,13) | BK43: =INDEX($C$32:$BV$32,12) | BL43: =INDEX($C$32:$BV$32,11) | BM43: =INDEX($C$32:$BV$32,10) | BN43: =INDEX($C$32:$BV$32,9) | BO43: =INDEX($C$32:$BV$32,8) | BP43: =INDEX($C$32:$BV$32,7) | BQ43: =INDEX($C$32:$BV$32,6) | BR43: =INDEX($C$32:$BV$32,5) | BS43: =INDEX($C$32:$BV$32,4) | BT43: =INDEX($C$32:$BV$32,3) | BU43: =INDEX($C$32:$BV$32,2) | BV43: =INDEX($C$32:$BV$32,1)
...

Sheet Eras
A1: line | B1: segment | C1: 2025-01 | D1: 2025-02 | E1: 2025-03 | F1: 2025-04 | G1: 2025-05 | H1: 2025-06 | I1: 2025-07 | J1: 2025-08 | K1: 2025-09 | L1: 2025-10 | M1: 2025-11 | N1: 2025-12 | O1: 2026-01 | P1: 2026-02 | Q1: 2026-03 | R1: 2026-04 | S1: 2026-05 | T1: 2026-06 | U1: 2026-07 | V1: 2026-08 | W1: 2026-09 | X1: 2026-10 | Y1: 2026-11 | Z1: 2026-12 | AA1: 2027-01 | AB1: 2027-02 | AC1: 2027-03 | AD1: 2027-04 | AE1: 2027-05 | AF1: 2027-06 | AG1: 2027-07 | AH1: 2027-08 | AI1: 2027-09 | AJ1: 2027-10 | AK1: 2027-11 | AL1: 2027-12 | AM1: 2028-01 | AN1: 2028-02 | AO1: 2028-03 | AP1: 2028-04 | AQ1: 2028-05 | AR1: 2028-06 | AS1: 2028-07 | AT1: 2028-08 | AU1: 2028-09 | AV1: 2028-10 | AW1: 2028-11 | AX1: 2028-12 | AY1: 2029-01 | AZ1: 2029-02 | BA1: 2029-03 | BB1: 2029-04 | BC1: 2029-05 | BD1: 2029-06 | BE1: 2029-07 | BF1: 2029-08 | BG1: 2029-09 | BH1: 2029-10 | BI1: 2029-11 | BJ1: 2029-12 | BK1: 2030-01 | BL1: 2030-02 | BM1: 2030-03 | BN1: 2030-04 | BO1: 2030-05 | BP1: 2030-06 | BQ1: 2030-07 | BR1: 2030-08 | BS1: 2030-09 | BT1: 2030-10 | BU1: 2030-11 | BV1: 2030-12
A2: month index (0 = Jan 2025) | C2: 0 | D2: 1 | E2: 2 | F2: 3 | G2: 4 | H2: 5 | I2: 6 | J2: 7 | K2: 8 | L2: 9 | M2: 10 | N2: 11 | O2: 12 | P2: 13 | Q2: 14 | R2: 15 | S2: 16 | T2: 17 | U2: 18 | V2: 19 | W2: 20 | X2: 21 | Y2: 22 | Z2: 23 | AA2: 24 | AB2: 25 | AC2: 26 | AD2: 27 | AE2: 28 | AF2: 29 | AG2: 30 | AH2: 31 | AI2: 32 | AJ2: 33 | AK2: 34 | AL2: 35 | AM2: 36 | AN2: 37 | AO2: 38 | AP2: 39 | AQ2: 40 | AR2: 41 | AS2: 42 | AT2: 43 | AU2: 44 | AV2: 45 | AW2: 46 | AX2: 47 | AY2: 48 | AZ2: 49 | BA2: 50 | BB2: 51 | BC2: 52 | BD2: 53 | BE2: 54 | BF2: 55 | BG2: 56 | BH2: 57 | BI2: 58 | BJ2: 59 | BK2: 60 | BL2: 61 | BM2: 62 | BN2: 63 | BO2: 64 | BP2: 65 | BQ2: 66 | BR2: 67 | BS2: 68 | BT2: 69 | BU2: 70 | BV2: 71
A3: era @0 history | B3: mask | C3: =IF(C$2<(Params!$B$8-1),1,0) | D3: =IF(D$2<(Params!$B$8-1),1,0) | E3: =IF(E$2<(Params!$B$8-1),1,0) | F3: =IF(F$2<(Params!$B$8-1),1,0) | G3: =IF(G$2<(Params!$B$8-1),1,0) | H3: =IF(H$2<(Params!$B$8-1),1,0) | I3: =IF(I$2<(Params!$B$8-1),1,0) | J3: =IF(J$2<(Params!$B$8-1),1,0) | ... BV3: =IF(BV$2<(Params!$B$8-1),1,0)
A4: era @1 forecast | B4: mask | C4: =1-C3-C5 | D4: =1-D3-D5 | E4: =1-E3-E5 | F4: =1-F3-F5 | G4: =1-G3-G5 | H4: =1-H3-H5 | I4: =1-I3-I5 | J4: =1-J3-J5 | ... BV4: =1-BV3-BV5
A5: era @2 experiment | B5: mask | C5: =IF(AND(C$2>=(Params!$B$8-1),Params!$B$9=1,C$2>=(Params!$B$10-1)),1,0) | D5: =IF(AND(D$2>=(Params!$B$8-1),Params!$B$9=1,D$2>=(Params!$B$10-1)),1,0) | E5: =IF(AND(E$2>=(Params!$B$8-1),Params!$B$9=1,E$2>=(Params!$B$10-1)),1,0) | F5: =IF(AND(F$2>=(Params!$B$8-1),Params!$B$9=1,F$2>=(Params!$B$10-1)),1,0) | G5: =IF(AND(G$2>=(Params!$B$8-1),Params!$B$9=1,G$2>=(Params!$B$10-1)),1,0) | H5: =IF(AND(H$2>=(Params!$B$8-1),Params!$B$9=1,H$2>=(Params!$B$10-1)),1,0) | I5: =IF(AND(I$2>=(Params!$B$8-1),Params!$B$9=1,I$2>=(Params!$B$10-1)),1,0) | J5: =IF(AND(J$2>=(Params!$B$8-1),Params!$B$9=1,J$2>=(Params!$B$10-1)),1,0) | ... BV5: =IF(AND(BV$2>=(Params!$B$8-1),Params!$B$9=1,BV$2>=(Params!$B$10-1)),1,0)
A7: conversion multiplier | B7: by month | C7: =(C3*Params!$B$26+(C4+C5)*Params!$B$27)*(1+Params!$B$11*C5) | D7: =(D3*Params!$B$26+(D4+D5)*Params!$B$27)*(1+Params!$B$11*D5) | E7: =(E3*Params!$B$26+(E4+E5)*Params!$B$27)*(1+Params!$B$11*E5) | F7: =(F3*Params!$B$26+(F4+F5)*Params!$B$27)*(1+Params!$B$11*F5) | G7: =(G3*Params!$B$26+(G4+G5)*Params!$B$27)*(1+Params!$B$11*G5) | H7: =(H3*Params!$B$26+(H4+H5)*Params!$B$27)*(1+Params!$B$11*H5) | I7: =(I3*Params!$B$26+(I4+I5)*Params!$B$27)*(1+Params!$B$11*I5) | J7: =(J3*Params!$B$26+(J4+J5)*Params!$B$27)*(1+Params!$B$11*J5) | ... BV7: =(BV3*Params!$B$26+(BV4+BV5)*Params!$B$27)*(1+Params!$B$11*BV5)
