Workbook

Sheet README
A1: Discord Nitro subscription revenue model (portfolio project). All Discord figures are third-party estimates.
A2: Scenario: base. Generated by nitro_model.excel_export from data/assumptions.csv; mirrors src/nitro_model/cohorts.py.
A3: Flow: Assumptions -> Params -> Curves / MAU / Prices -> Adds -> Paid, Legacy, React -> Subs -> Revenue -> Checks.
A4: Change inputs only on the Assumptions sheet (yellow cells on Params link there). Params!k_cal is solved in Python.
A5: Active subscribers = SUMPRODUCT(sign-ups to date, reversed survival curve). Cohort_US_NitroM shows one segment as a full triangle.
A6: Revenue is at reference (FY2025 average) FX; the FX path arrives in Milestone 3.

Sheet Assumptions
A1: id | B1: group | C1: segment | D1: scenario | E1: value | F1: unit | G1: low | H1: high | I1: status | J1: source_ids | K1: as_of | L1: notes
A2: model_start_year | B2: timeline | C2: all | D2: all | E2: 2025 | F2: year | I2: design | J2: P01 | K2: 2026-10-27 | L2: FY2025 is the calibration year against public estimates
A3: model_start_month | B3: timeline | C3: all | D3: all | E3: 1 | F3: month | I3: design | J3: P01 | K3: 2026-10-27
A4: horizon_months | B4: timeline | C4: all | D4: all | E4: 72 | F4: months | I4: design | J4: P01 | K4: 2026-10-27 | L4: Jan 2025 to Dec 2030: 12 calibration months + 60 forecast months
A5: mau_jan2025 | B5: mau | C5: all | D5: all | E5: 225 | F5: M users | G5: 200 | H5: 260 | I5: proposed | J5: S06;S02;S03;A01 | K5: 2026-10-27 | L5: Discord says 200M+ (May 2025); trackers say 227.7M (2024) to 250-259M (2025). Start below tracker midpoint: trackers likely mix visits and registered users
A6: mau_share | B6: mau | C6: US_CA | D6: all | E6: 0.31 | F6: share | G6: 0.27 | H6: 0.35 | I6: proposed | J6: S07;A01 | K6: 2026-10-27 | L6: Semrush web traffic US 29.1% plus Canada. Caveat: web traffic misses desktop-app and mobile-app use so regional mix may skew; conv_rate by region absorbs part of the error
A7: mau_share | B7: mau | C7: EUROPE | D7: all | E7: 0.28 | F7: share | G7: 0.22 | H7: 0.32 | I7: proposed | J7: S07;A01 | K7: 2026-10-27 | L7: No direct Europe figure found; judgment from country traffic tail (DE/FR/UK/PL)
A8: mau_share | B8: mau | C8: LATAM | D8: all | E8: 0.14 | F8: share | G8: 0.1 | H8: 0.18 | I8: proposed | J8: S07;A01 | K8: 2026-10-27 | L8: Brazil 7.25% of traffic plus rest of LatAm
A9: mau_share | B9: mau | C9: APAC | D9: all | E9: 0.15 | F9: share | G9: 0.1 | H9: 0.2 | I9: proposed | J9: S07;A01 | K9: 2026-10-27 | L9: India 4.9% of traffic plus Japan/SEA/ANZ
A10: mau_share | B10: mau | C10: ROW | D10: all | E10: 0.12 | F10: share | G10: 0.08 | H10: 0.16 | I10: proposed | J10: S07;A01 | K10: 2026-10-27 | L10: Turkey, Russia, MENA, Africa
A11: mau_growth_first | B11: mau | C11: all | D11: base | E11: 0.1 | F11: YoY | G11: 0.06 | H11: 0.14 | I11: proposed | J11: S02;S03;A01 | K11: 2026-10-27 | L11: Tracker YoY 2024-25: 8.7% (Resourcera) to 13.8% (Feedough); applies to 2025
A12: mau_growth_first | B12: mau | C12: all | D12: upside | E12: 0.13 | F12: YoY | G12: 0.1 | H12: 0.16 | I12: proposed | J12: S02;A01 | K12: 2026-10-27 | L12: Near the high tracker growth rate
A13: mau_growth_first | B13: mau | C13: all | D13: downside | E13: 0.06 | F13: YoY | G13: 0.03 | H13: 0.09 | I13: proposed | J13: A01 | K13: 2026-10-27
A14: mau_growth_last | B14: mau | C14: all | D14: base | E14: 0.04 | F14: YoY | G14: 0.02 | H14: 0.06 | I14: proposed | J14: A01 | K14: 2026-10-27 | L14: Applies to 2030; linear fade from first-year growth
A15: mau_growth_last | B15: mau | C15: all | D15: upside | E15: 0.06 | F15: YoY | G15: 0.04 | H15: 0.08 | I15: proposed | J15: A01 | K15: 2026-10-27
A16: mau_growth_last | B16: mau | C16: all | D16: downside | E16: 0 | F16: YoY | G16: -0.03 | H16: 0.02 | I16: proposed | J16: A01 | K16: 2026-10-27 | L16: Flat MAU by 2030
A17: conv_rate | B17: conversion | C17: US_CA | D17: all | E17: 0.0045 | F17: gross adds / MAU / month | G17: 0.003 | H17: 0.006 | I17: proposed | J17: A01 | K17: 2026-10-27 | L17: Back-solved: ~0.65M gross adds/mo holds ~7.3M subs at a ~13-month blended lifetime. Split by willingness to pay. Recalibrated in M3
A18: conv_rate | B18: conversion | C18: EUROPE | D18: all | E18: 0.0032 | F18: gross adds / MAU / month | G18: 0.002 | H18: 0.0045 | I18: proposed | J18: A01 | K18: 2026-10-27
A19: conv_rate | B19: conversion | C19: LATAM | D19: all | E19: 0.0015 | F19: gross adds / MAU / month | G19: 0.0008 | H19: 0.0025 | I19: proposed | J19: A01 | K19: 2026-10-27
A20: conv_rate | B20: conversion | C20: APAC | D20: all | E20: 0.0018 | F20: gross adds / MAU / month | G20: 0.001 | H20: 0.0028 | I20: proposed | J20: A01 | K20: 2026-10-27
A21: conv_rate | B21: conversion | C21: ROW | D21: all | E21: 0.0015 | F21: gross adds / MAU / month | G21: 0.0008 | H21: 0.0025 | I21: proposed | J21: A01 | K21: 2026-10-27
A22: conv_multiplier | B22: conversion | C22: all | D22: base | E22: 1 | F22: x | I22: design | J22: P01 | K22: 2026-10-27
A23: conv_multiplier | B23: conversion | C23: all | D23: upside | E23: 1.1 | F23: x | G23: 1.05 | H23: 1.2 | I23: proposed | J23: A01 | K23: 2026-10-27
A24: conv_multiplier | B24: conversion | C24: all | D24: downside | E24: 0.9 | F24: x | G24: 0.8 | H24: 0.95 | I24: proposed | J24: A01 | K24: 2026-10-27
A25: plan_mix | B25: mix_plan | C25: NITRO_M | D25: all | E25: 0.45 | F25: share of gross adds | G25: 0.35 | H25: 0.55 | I25: proposed | J25: A01 | K25: 2026-10-27 | L25: No public plan mix. Drives most of the ARPU gap vs list price
A26: plan_mix | B26: mix_plan | C26: NITRO_A | D26: all | E26: 0.15 | F26: share of gross adds | G26: 0.08 | H26: 0.25 | I26: proposed | J26: S15;A01 | K26: 2026-10-27 | L26: Duolingo shows annual share can reach 47-71% when pushed hard; Discord does not push annual that hard
A27: plan_mix | B27: mix_plan | C27: BASIC_M | D27: all | E27: 0.32 | F27: share of gross adds | G27: 0.2 | H27: 0.45 | I27: proposed | J27: A01 | K27: 2026-10-27
A28: plan_mix | B28: mix_plan | C28: BASIC_A | D28: all | E28: 0.08 | F28: share of gross adds | G28: 0.03 | H28: 0.15 | I28: proposed | J28: A01 | K28: 2026-10-27
A29: platform_mix | B29: mix_platform | C29: US_CA|WEB | D29: all | E29: 0.55 | F29: share of gross adds | G29: 0.45 | H29: 0.65 | I29: proposed | J29: A01 | K29: 2026-10-27 | L29: Desktop-first product; web/desktop billing avoids app store fees
A30: platform_mix | B30: mix_platform | C30: US_CA|IOS | D30: all | E30: 0.3 | F30: share of gross adds | G30: 0.2 | H30: 0.4 | I30: proposed | J30: A01 | K30: 2026-10-27 | L30: High iPhone share in US
A31: platform_mix | B31: mix_platform | C31: US_CA|ANDROID | D31: all | E31: 0.15 | F31: share of gross adds | G31: 0.1 | H31: 0.2 | I31: proposed | J31: A01 | K31: 2026-10-27
A32: platform_mix | B32: mix_platform | C32: EUROPE|WEB | D32: all | E32: 0.6 | F32: share of gross adds | G32: 0.5 | H32: 0.7 | I32: proposed | J32: A01 | K32: 2026-10-27
A33: platform_mix | B33: mix_platform | C33: EUROPE|IOS | D33: all | E33: 0.22 | F33: share of gross adds | G33: 0.15 | H33: 0.3 | I33: proposed | J33: A01 | K33: 2026-10-27
A34: platform_mix | B34: mix_platform | C34: EUROPE|ANDROID | D34: all | E34: 0.18 | F34: share of gross adds | G34: 0.12 | H34: 0.25 | I34: proposed | J34: A01 | K34: 2026-10-27
A35: platform_mix | B35: mix_platform | C35: LATAM|WEB | D35: all | E35: 0.55 | F35: share of gross adds | G35: 0.45 | H35: 0.65 | I35: proposed | J35: A01 | K35: 2026-10-27
A36: platform_mix | B36: mix_platform | C36: LATAM|IOS | D36: all | E36: 0.1 | F36: share of gross adds | G36: 0.05 | H36: 0.15 | I36: proposed | J36: A01 | K36: 2026-10-27 | L36: Android-dominant region
A37: platform_mix | B37: mix_platform | C37: LATAM|ANDROID | D37: all | E37: 0.35 | F37: share of gross adds | G37: 0.25 | H37: 0.45 | I37: proposed | J37: A01 | K37: 2026-10-27
A38: platform_mix | B38: mix_platform | C38: APAC|WEB | D38: all | E38: 0.55 | F38: share of gross adds | G38: 0.45 | H38: 0.65 | I38: proposed | J38: A01 | K38: 2026-10-27
A39: platform_mix | B39: mix_platform | C39: APAC|IOS | D39: all | E39: 0.2 | F39: share of gross adds | G39: 0.1 | H39: 0.3 | I39: proposed | J39: A01 | K39: 2026-10-27 | L39: Japan iOS-heavy; India Android-heavy
A40: platform_mix | B40: mix_platform | C40: APAC|ANDROID | D40: all | E40: 0.25 | F40: share of gross adds | G40: 0.15 | H40: 0.35 | I40: proposed | J40: A01 | K40: 2026-10-27
...

Sheet Params
A1: param | B1: value | C1: linked to
A2: mau0 | B2: =Assumptions!$E$5*1e+06 | C2: mau_jan2025[all]
A3: mau_growth_first | B3: =Assumptions!$E$11 | C3: mau_growth_first[all]
A4: mau_growth_last | B4: =Assumptions!$E$14 | C4: mau_growth_last[all]
A5: conv_multiplier | B5: =Assumptions!$E$22 | C5: conv_multiplier[all]
A6: trial_share | B6: =Assumptions!$E$95 | C6: trial_share[all]
A7: trial_months | B7: =Assumptions!$E$96 | C7: trial_months[all]
A8: trial_to_paid | B8: =Assumptions!$E$97 | C8: trial_to_paid[all]
A9: count_trials_as_subs | B9: =Assumptions!$E$100 | C9: count_trials_as_subs[all]
A10: churn_m1 | B10: =Assumptions!$E$44 | C10: churn_m1[MONTHLY]
A11: churn_m2 | B11: =Assumptions!$E$47 | C11: churn_m2[MONTHLY]
A12: churn_m3 | B12: =Assumptions!$E$50 | C12: churn_m3[MONTHLY]
A13: churn_tail | B13: =Assumptions!$E$53 | C13: churn_tail[MONTHLY]
A14: annual_renewal_first | B14: =Assumptions!$E$56 | C14: annual_renewal_first[ANNUAL]
A15: annual_renewal_later | B15: =Assumptions!$E$59 | C15: annual_renewal_later[ANNUAL]
A16: react_rate | B16: =Assumptions!$E$62 | C16: react_rate[all]
A17: react_window_months | B17: =Assumptions!$E$65 | C17: react_window_months[all]
A18: react_churn_tail | B18: =Assumptions!$E$66 | C18: react_churn_tail[all]
A19: open_subs | B19: =Assumptions!$E$67*1e+06 | C19: open_subs[all]
A20: open_churn_tail | B20: =Assumptions!$E$78 | C20: open_churn_tail[MONTHLY]
A21: open_y1_share | B21: =Assumptions!$E$77 | C21: open_y1_share[all]
A22: avg_discount | B22: =Assumptions!$E$101 | C22: avg_discount[all]
A23: fee_web | B23: =Assumptions!$E$105 | C23: store_fee[WEB]
A24: fee_ios_y1 | B24: =Assumptions!$E$102 | C24: store_fee[IOS_Y1]
A25: fee_ios_later | B25: =Assumptions!$E$103 | C25: store_fee[IOS_LATER]
A26: fee_android | B26: =Assumptions!$E$104 | C26: store_fee[ANDROID]
A27: cal_target_subs | B27: =Assumptions!$E$134*1e+06 | C27: cal_subs_mid2025[all]
A28: cal_month_index | B28: =Assumptions!$E$135 | C28: cal_month_index[all]
A29: cal_rev_low | B29: =Assumptions!$G$137*1000000 | C29: cal_nitro_rev_2025 low
A30: cal_rev_high | B30: =Assumptions!$H$137*1000000 | C30: cal_nitro_rev_2025 high
A31: mau_share[US_CA] | B31: =Assumptions!$E$6 | C31: mau_share[US_CA]
A32: mau_share[EUROPE] | B32: =Assumptions!$E$7 | C32: mau_share[EUROPE]
A33: mau_share[LATAM] | B33: =Assumptions!$E$8 | C33: mau_share[LATAM]
A34: mau_share[APAC] | B34: =Assumptions!$E$9 | C34: mau_share[APAC]
A35: mau_share[ROW] | B35: =Assumptions!$E$10 | C35: mau_share[ROW]
A36: conv_rate[US_CA] | B36: =Assumptions!$E$17 | C36: conv_rate[US_CA]
A37: conv_rate[EUROPE] | B37: =Assumptions!$E$18 | C37: conv_rate[EUROPE]
A38: conv_rate[LATAM] | B38: =Assumptions!$E$19 | C38: conv_rate[LATAM]
A39: conv_rate[APAC] | B39: =Assumptions!$E$20 | C39: conv_rate[APAC]
A40: conv_rate[ROW] | B40: =Assumptions!$E$21 | C40: conv_rate[ROW]
...

Sheet Curves
A1: curve | B1: age (months) -> | C1: 0 | D1: 1 | E1: 2 | F1: 3 | G1: 4 | H1: 5 | I1: 6 | J1: 7 | K1: 8 | L1: 9 | M1: 10 | N1: 11 | O1: 12 | P1: 13 | Q1: 14 | R1: 15 | S1: 16 | T1: 17 | U1: 18 | V1: 19 | W1: 20 | X1: 21 | Y1: 22 | Z1: 23 | AA1: 24 | AB1: 25 | AC1: 26 | AD1: 27 | AE1: 28 | AF1: 29 | AG1: 30 | AH1: 31 | AI1: 32 | AJ1: 33 | AK1: 34 | AL1: 35 | AM1: 36 | AN1: 37 | AO1: 38 | AP1: 39 | AQ1: 40 | AR1: 41 | AS1: 42 | AT1: 43 | AU1: 44 | AV1: 45 | AW1: 46 | AX1: 47 | AY1: 48 | AZ1: 49 | BA1: 50 | BB1: 51 | BC1: 52 | BD1: 53 | BE1: 54 | BF1: 55 | BG1: 56 | BH1: 57 | BI1: 58 | BJ1: 59 | BK1: 60 | BL1: 61 | BM1: 62 | BN1: 63 | BO1: 64 | BP1: 65 | BQ1: 66 | BR1: 67 | BS1: 68 | BT1: 69 | BU1: 70 | BV1: 71
A2: S_MONTHLY | C2: =1 | D2: =C2*(1-IF(D$1=1,Params!$B$10,IF(D$1=2,Params!$B$11,IF(D$1=3,Params!$B$12,Params!$B$13)))) | E2: =D2*(1-IF(E$1=1,Params!$B$10,IF(E$1=2,Params!$B$11,IF(E$1=3,Params!$B$12,Params!$B$13)))) | F2: =E2*(1-IF(F$1=1,Params!$B$10,IF(F$1=2,Params!$B$11,IF(F$1=3,Params!$B$12,Params!$B$13)))) | G2: =F2*(1-IF(G$1=1,Params!$B$10,IF(G$1=2,Params!$B$11,IF(G$1=3,Params!$B$12,Params!$B$13)))) | H2: =G2*(1-IF(H$1=1,Params!$B$10,IF(H$1=2,Params!$B$11,IF(H$1=3,Params!$B$12,Params!$B$13)))) | I2: =H2*(1-IF(I$1=1,Params!$B$10,IF(I$1=2,Params!$B$11,IF(I$1=3,Params!$B$12,Params!$B$13)))) | J2: =I2*(1-IF(J$1=1,Params!$B$10,IF(J$1=2,Params!$B$11,IF(J$1=3,Params!$B$12,Params!$B$13)))) | K2: =J2*(1-IF(K$1=1,Params!$B$10,IF(K$1=2,Params!$B$11,IF(K$1=3,Params!$B$12,Params!$B$13)))) | ... BV2: =BU2*(1-IF(BV$1=1,Params!$B$10,IF(BV$1=2,Params!$B$11,IF(BV$1=3,Params!$B$12,Params!$B$13))))
A3: S_ANNUAL | C3: =IF(C$1<12,1,Params!$B$14*Params!$B$15^(INT(C$1/12)-1)) | D3: =IF(D$1<12,1,Params!$B$14*Params!$B$15^(INT(D$1/12)-1)) | E3: =IF(E$1<12,1,Params!$B$14*Params!$B$15^(INT(E$1/12)-1)) | F3: =IF(F$1<12,1,Params!$B$14*Params!$B$15^(INT(F$1/12)-1)) | G3: =IF(G$1<12,1,Params!$B$14*Params!$B$15^(INT(G$1/12)-1)) | H3: =IF(H$1<12,1,Params!$B$14*Params!$B$15^(INT(H$1/12)-1)) | I3: =IF(I$1<12,1,Params!$B$14*Params!$B$15^(INT(I$1/12)-1)) | J3: =IF(J$1<12,1,Params!$B$14*Params!$B$15^(INT(J$1/12)-1)) | ... BV3: =IF(BV$1<12,1,Params!$B$14*Params!$B$15^(INT(BV$1/12)-1))
A4: D_MONTHLY | C4: =0 | D4: =C2-D2 | E4: =D2-E2 | F4: =E2-F2 | G4: =F2-G2 | H4: =G2-H2 | I4: =H2-I2 | J4: =I2-J2 | K4: =J2-K2 | ... BV4: =BU2-BV2
A5: D_ANNUAL | C5: =0 | D5: =C3-D3 | E5: =D3-E3 | F5: =E3-F3 | G5: =F3-G3 | H5: =G3-H3 | I5: =H3-I3 | J5: =I3-J3 | K5: =J3-K3 | ... BV5: =BU3-BV3
A6: S_REACT | C6: =(1-Params!$B$18)^C$1 | D6: =(1-Params!$B$18)^D$1 | E6: =(1-Params!$B$18)^E$1 | F6: =(1-Params!$B$18)^F$1 | G6: =(1-Params!$B$18)^G$1 | H6: =(1-Params!$B$18)^H$1 | I6: =(1-Params!$B$18)^I$1 | J6: =(1-Params!$B$18)^J$1 | ... BV6: =(1-Params!$B$18)^BV$1
A7: D_REACT | C7: =0 | D7: =C6-D6 | E7: =D6-E6 | F7: =E6-F6 | G7: =F6-G6 | H7: =G6-H6 | I7: =H6-I6 | J7: =I6-J6 | K7: =J6-K6 | ... BV7: =BU6-BV6
A8: K_REACT | C8: =IF(AND(C$1>=1,C$1<=Params!$B$17),Params!$B$16*(1-Params!$B$16)^(C$1-1),0) | D8: =IF(AND(D$1>=1,D$1<=Params!$B$17),Params!$B$16*(1-Params!$B$16)^(D$1-1),0) | E8: =IF(AND(E$1>=1,E$1<=Params!$B$17),Params!$B$16*(1-Params!$B$16)^(E$1-1),0) | F8: =IF(AND(F$1>=1,F$1<=Params!$B$17),Params!$B$16*(1-Params!$B$16)^(F$1-1),0) | G8: =IF(AND(G$1>=1,G$1<=Params!$B$17),Params!$B$16*(1-Params!$B$16)^(G$1-1),0) | H8: =IF(AND(H$1>=1,H$1<=Params!$B$17),Params!$B$16*(1-Params!$B$16)^(H$1-1),0) | I8: =IF(AND(I$1>=1,I$1<=Params!$B$17),Params!$B$16*(1-Params!$B$16)^(I$1-1),0) | J8: =IF(AND(J$1>=1,J$1<=Params!$B$17),Params!$B$16*(1-Params!$B$16)^(J$1-1),0) | ... BV8: =IF(AND(BV$1>=1,BV$1<=Params!$B$17),Params!$B$16*(1-Params!$B$16)^(BV$1-1),0)
A9: S_MONTHLY_Y1 | C9: =IF(C$1<12,C2,0) | D9: =IF(D$1<12,D2,0) | E9: =IF(E$1<12,E2,0) | F9: =IF(F$1<12,F2,0) | G9: =IF(G$1<12,G2,0) | H9: =IF(H$1<12,H2,0) | I9: =IF(I$1<12,I2,0) | J9: =IF(J$1<12,J2,0) | ... BV9: =IF(BV$1<12,BV2,0)
A10: S_ANNUAL_Y1 | C10: =IF(C$1<12,C3,0) | D10: =IF(D$1<12,D3,0) | E10: =IF(E$1<12,E3,0) | F10: =IF(F$1<12,F3,0) | G10: =IF(G$1<12,G3,0) | H10: =IF(H$1<12,H3,0) | I10: =IF(I$1<12,I3,0) | J10: =IF(J$1<12,J3,0) | ... BV10: =IF(BV$1<12,BV3,0)
A11: S_REACT_Y1 | C11: =IF(C$1<12,C6,0) | D11: =IF(D$1<12,D6,0) | E11: =IF(E$1<12,E6,0) | F11: =IF(F$1<12,F6,0) | G11: =IF(G$1<12,G6,0) | H11: =IF(H$1<12,H6,0) | I11: =IF(I$1<12,I6,0) | J11: =IF(J$1<12,J6,0) | ... BV11: =IF(BV$1<12,BV6,0)
A12: Reversed rows run oldest age first so SUMPRODUCT can pair them with sign-ups to date.
A13: S_MONTHLY reversed | C13: =INDEX($C$2:$BV$2,72) | D13: =INDEX($C$2:$BV$2,71) | E13: =INDEX($C$2:$BV$2,70) | F13: =INDEX($C$2:$BV$2,69) | G13: =INDEX($C$2:$BV$2,68) | H13: =INDEX($C$2:$BV$2,67) | I13: =INDEX($C$2:$BV$2,66) | J13: =INDEX($C$2:$BV$2,65) | K13: =INDEX($C$2:$BV$2,64) | L13: =INDEX($C$2:$BV$2,63) | M13: =INDEX($C$2:$BV$2,62) | N13: =INDEX($C$2:$BV$2,61) | O13: =INDEX($C$2:$BV$2,60) | P13: =INDEX($C$2:$BV$2,59) | Q13: =INDEX($C$2:$BV$2,58) | R13: =INDEX($C$2:$BV$2,57) | S13: =INDEX($C$2:$BV$2,56) | T13: =INDEX($C$2:$BV$2,55) | U13: =INDEX($C$2:$BV$2,54) | V13: =INDEX($C$2:$BV$2,53) | W13: =INDEX($C$2:$BV$2,52) | X13: =INDEX($C$2:$BV$2,51) | Y13: =INDEX($C$2:$BV$2,50) | Z13: =INDEX($C$2:$BV$2,49) | AA13: =INDEX($C$2:$BV$2,48) | AB13: =INDEX($C$2:$BV$2,47) | AC13: =INDEX($C$2:$BV$2,46) | AD13: =INDEX($C$2:$BV$2,45) | AE13: =INDEX($C$2:$BV$2,44) | AF13: =INDEX($C$2:$BV$2,43) | AG13: =INDEX($C$2:$BV$2,42) | AH13: =INDEX($C$2:$BV$2,41) | AI13: =INDEX($C$2:$BV$2,40) | AJ13: =INDEX($C$2:$BV$2,39) | AK13: =INDEX($C$2:$BV$2,38) | AL13: =INDEX($C$2:$BV$2,37) | AM13: =INDEX($C$2:$BV$2,36) | AN13: =INDEX($C$2:$BV$2,35) | AO13: =INDEX($C$2:$BV$2,34) | AP13: =INDEX($C$2:$BV$2,33) | AQ13: =INDEX($C$2:$BV$2,32) | AR13: =INDEX($C$2:$BV$2,31) | AS13: =INDEX($C$2:$BV$2,30) | AT13: =INDEX($C$2:$BV$2,29) | AU13: =INDEX($C$2:$BV$2,28) | AV13: =INDEX($C$2:$BV$2,27) | AW13: =INDEX($C$2:$BV$2,26) | AX13: =INDEX($C$2:$BV$2,25) | AY13: =INDEX($C$2:$BV$2,24) | AZ13: =INDEX($C$2:$BV$2,23) | BA13: =INDEX($C$2:$BV$2,22) | BB13: =INDEX($C$2:$BV$2,21) | BC13: =INDEX($C$2:$BV$2,20) | BD13: =INDEX($C$2:$BV$2,19) | BE13: =INDEX($C$2:$BV$2,18) | BF13: =INDEX($C$2:$BV$2,17) | BG13: =INDEX($C$2:$BV$2,16) | BH13: =INDEX($C$2:$BV$2,15) | BI13: =INDEX($C$2:$BV$2,14) | BJ13: =INDEX($C$2:$BV$2,13) | BK13: =INDEX($C$2:$BV$2,12) | BL13: =INDEX($C$2:$BV$2,11) | BM13: =INDEX($C$2:$BV$2,10) | BN13: =INDEX($C$2:$BV$2,9) | BO13: =INDEX($C$2:$BV$2,8) | BP13: =INDEX($C$2:$BV$2,7) | BQ13: =INDEX($C$2:$BV$2,6) | BR13: =INDEX($C$2:$BV$2,5) | BS13: =INDEX($C$2:$BV$2,4) | BT13: =INDEX($C$2:$BV$2,3) | BU13: =INDEX($C$2:$BV$2,2) | BV13: =INDEX($C$2:$BV$2,1)
A14: S_ANNUAL reversed | C14: =INDEX($C$3:$BV$3,72) | D14: =INDEX($C$3:$BV$3,71) | E14: =INDEX($C$3:$BV$3,70) | F14: =INDEX($C$3:$BV$3,69) | G14: =INDEX($C$3:$BV$3,68) | H14: =INDEX($C$3:$BV$3,67) | I14: =INDEX($C$3:$BV$3,66) | J14: =INDEX($C$3:$BV$3,65) | K14: =INDEX($C$3:$BV$3,64) | L14: =INDEX($C$3:$BV$3,63) | M14: =INDEX($C$3:$BV$3,62) | N14: =INDEX($C$3:$BV$3,61) | O14: =INDEX($C$3:$BV$3,60) | P14: =INDEX($C$3:$BV$3,59) | Q14: =INDEX($C$3:$BV$3,58) | R14: =INDEX($C$3:$BV$3,57) | S14: =INDEX($C$3:$BV$3,56) | T14: =INDEX($C$3:$BV$3,55) | U14: =INDEX($C$3:$BV$3,54) | V14: =INDEX($C$3:$BV$3,53) | W14: =INDEX($C$3:$BV$3,52) | X14: =INDEX($C$3:$BV$3,51) | Y14: =INDEX($C$3:$BV$3,50) | Z14: =INDEX($C$3:$BV$3,49) | AA14: =INDEX($C$3:$BV$3,48) | AB14: =INDEX($C$3:$BV$3,47) | AC14: =INDEX($C$3:$BV$3,46) | AD14: =INDEX($C$3:$BV$3,45) | AE14: =INDEX($C$3:$BV$3,44) | AF14: =INDEX($C$3:$BV$3,43) | AG14: =INDEX($C$3:$BV$3,42) | AH14: =INDEX($C$3:$BV$3,41) | AI14: =INDEX($C$3:$BV$3,40) | AJ14: =INDEX($C$3:$BV$3,39) | AK14: =INDEX($C$3:$BV$3,38) | AL14: =INDEX($C$3:$BV$3,37) | AM14: =INDEX($C$3:$BV$3,36) | AN14: =INDEX($C$3:$BV$3,35) | AO14: =INDEX($C$3:$BV$3,34) | AP14: =INDEX($C$3:$BV$3,33) | AQ14: =INDEX($C$3:$BV$3,32) | AR14: =INDEX($C$3:$BV$3,31) | AS14: =INDEX($C$3:$BV$3,30) | AT14: =INDEX($C$3:$BV$3,29) | AU14: =INDEX($C$3:$BV$3,28) | AV14: =INDEX($C$3:$BV$3,27) | AW14: =INDEX($C$3:$BV$3,26) | AX14: =INDEX($C$3:$BV$3,25) | AY14: =INDEX($C$3:$BV$3,24) | AZ14: =INDEX($C$3:$BV$3,23) | BA14: =INDEX($C$3:$BV$3,22) | BB14: =INDEX($C$3:$BV$3,21) | BC14: =INDEX($C$3:$BV$3,20) | BD14: =INDEX($C$3:$BV$3,19) | BE14: =INDEX($C$3:$BV$3,18) | BF14: =INDEX($C$3:$BV$3,17) | BG14: =INDEX($C$3:$BV$3,16) | BH14: =INDEX($C$3:$BV$3,15) | BI14: =INDEX($C$3:$BV$3,14) | BJ14: =INDEX($C$3:$BV$3,13) | BK14: =INDEX($C$3:$BV$3,12) | BL14: =INDEX($C$3:$BV$3,11) | BM14: =INDEX($C$3:$BV$3,10) | BN14: =INDEX($C$3:$BV$3,9) | BO14: =INDEX($C$3:$BV$3,8) | BP14: =INDEX($C$3:$BV$3,7) | BQ14: =INDEX($C$3:$BV$3,6) | BR14: =INDEX($C$3:$BV$3,5) | BS14: =INDEX($C$3:$BV$3,4) | BT14: =INDEX($C$3:$BV$3,3) | BU14: =INDEX($C$3:$BV$3,2) | BV14: =INDEX($C$3:$BV$3,1)
A15: D_MONTHLY reversed | C15: =INDEX($C$4:$BV$4,72) | D15: =INDEX($C$4:$BV$4,71) | E15: =INDEX($C$4:$BV$4,70) | F15: =INDEX($C$4:$BV$4,69) | G15: =INDEX($C$4:$BV$4,68) | H15: =INDEX($C$4:$BV$4,67) | I15: =INDEX($C$4:$BV$4,66) | J15: =INDEX($C$4:$BV$4,65) | K15: =INDEX($C$4:$BV$4,64) | L15: =INDEX($C$4:$BV$4,63) | M15: =INDEX($C$4:$BV$4,62) | N15: =INDEX($C$4:$BV$4,61) | O15: =INDEX($C$4:$BV$4,60) | P15: =INDEX($C$4:$BV$4,59) | Q15: =INDEX($C$4:$BV$4,58) | R15: =INDEX($C$4:$BV$4,57) | S15: =INDEX($C$4:$BV$4,56) | T15: =INDEX($C$4:$BV$4,55) | U15: =INDEX($C$4:$BV$4,54) | V15: =INDEX($C$4:$BV$4,53) | W15: =INDEX($C$4:$BV$4,52) | X15: =INDEX($C$4:$BV$4,51) | Y15: =INDEX($C$4:$BV$4,50) | Z15: =INDEX($C$4:$BV$4,49) | AA15: =INDEX($C$4:$BV$4,48) | AB15: =INDEX($C$4:$BV$4,47) | AC15: =INDEX($C$4:$BV$4,46) | AD15: =INDEX($C$4:$BV$4,45) | AE15: =INDEX($C$4:$BV$4,44) | AF15: =INDEX($C$4:$BV$4,43) | AG15: =INDEX($C$4:$BV$4,42) | AH15: =INDEX($C$4:$BV$4,41) | AI15: =INDEX($C$4:$BV$4,40) | AJ15: =INDEX($C$4:$BV$4,39) | AK15: =INDEX($C$4:$BV$4,38) | AL15: =INDEX($C$4:$BV$4,37) | AM15: =INDEX($C$4:$BV$4,36) | AN15: =INDEX($C$4:$BV$4,35) | AO15: =INDEX($C$4:$BV$4,34) | AP15: =INDEX($C$4:$BV$4,33) | AQ15: =INDEX($C$4:$BV$4,32) | AR15: =INDEX($C$4:$BV$4,31) | AS15: =INDEX($C$4:$BV$4,30) | AT15: =INDEX($C$4:$BV$4,29) | AU15: =INDEX($C$4:$BV$4,28) | AV15: =INDEX($C$4:$BV$4,27) | AW15: =INDEX($C$4:$BV$4,26) | AX15: =INDEX($C$4:$BV$4,25) | AY15: =INDEX($C$4:$BV$4,24) | AZ15: =INDEX($C$4:$BV$4,23) | BA15: =INDEX($C$4:$BV$4,22) | BB15: =INDEX($C$4:$BV$4,21) | BC15: =INDEX($C$4:$BV$4,20) | BD15: =INDEX($C$4:$BV$4,19) | BE15: =INDEX($C$4:$BV$4,18) | BF15: =INDEX($C$4:$BV$4,17) | BG15: =INDEX($C$4:$BV$4,16) | BH15: =INDEX($C$4:$BV$4,15) | BI15: =INDEX($C$4:$BV$4,14) | BJ15: =INDEX($C$4:$BV$4,13) | BK15: =INDEX($C$4:$BV$4,12) | BL15: =INDEX($C$4:$BV$4,11) | BM15: =INDEX($C$4:$BV$4,10) | BN15: =INDEX($C$4:$BV$4,9) | BO15: =INDEX($C$4:$BV$4,8) | BP15: =INDEX($C$4:$BV$4,7) | BQ15: =INDEX($C$4:$BV$4,6) | BR15: =INDEX($C$4:$BV$4,5) | BS15: =INDEX($C$4:$BV$4,4) | BT15: =INDEX($C$4:$BV$4,3) | BU15: =INDEX($C$4:$BV$4,2) | BV15: =INDEX($C$4:$BV$4,1)
A16: D_ANNUAL reversed | C16: =INDEX($C$5:$BV$5,72) | D16: =INDEX($C$5:$BV$5,71) | E16: =INDEX($C$5:$BV$5,70) | F16: =INDEX($C$5:$BV$5,69) | G16: =INDEX($C$5:$BV$5,68) | H16: =INDEX($C$5:$BV$5,67) | I16: =INDEX($C$5:$BV$5,66) | J16: =INDEX($C$5:$BV$5,65) | K16: =INDEX($C$5:$BV$5,64) | L16: =INDEX($C$5:$BV$5,63) | M16: =INDEX($C$5:$BV$5,62) | N16: =INDEX($C$5:$BV$5,61) | O16: =INDEX($C$5:$BV$5,60) | P16: =INDEX($C$5:$BV$5,59) | Q16: =INDEX($C$5:$BV$5,58) | R16: =INDEX($C$5:$BV$5,57) | S16: =INDEX($C$5:$BV$5,56) | T16: =INDEX($C$5:$BV$5,55) | U16: =INDEX($C$5:$BV$5,54) | V16: =INDEX($C$5:$BV$5,53) | W16: =INDEX($C$5:$BV$5,52) | X16: =INDEX($C$5:$BV$5,51) | Y16: =INDEX($C$5:$BV$5,50) | Z16: =INDEX($C$5:$BV$5,49) | AA16: =INDEX($C$5:$BV$5,48) | AB16: =INDEX($C$5:$BV$5,47) | AC16: =INDEX($C$5:$BV$5,46) | AD16: =INDEX($C$5:$BV$5,45) | AE16: =INDEX($C$5:$BV$5,44) | AF16: =INDEX($C$5:$BV$5,43) | AG16: =INDEX($C$5:$BV$5,42) | AH16: =INDEX($C$5:$BV$5,41) | AI16: =INDEX($C$5:$BV$5,40) | AJ16: =INDEX($C$5:$BV$5,39) | AK16: =INDEX($C$5:$BV$5,38) | AL16: =INDEX($C$5:$BV$5,37) | AM16: =INDEX($C$5:$BV$5,36) | AN16: =INDEX($C$5:$BV$5,35) | AO16: =INDEX($C$5:$BV$5,34) | AP16: =INDEX($C$5:$BV$5,33) | AQ16: =INDEX($C$5:$BV$5,32) | AR16: =INDEX($C$5:$BV$5,31) | AS16: =INDEX($C$5:$BV$5,30) | AT16: =INDEX($C$5:$BV$5,29) | AU16: =INDEX($C$5:$BV$5,28) | AV16: =INDEX($C$5:$BV$5,27) | AW16: =INDEX($C$5:$BV$5,26) | AX16: =INDEX($C$5:$BV$5,25) | AY16: =INDEX($C$5:$BV$5,24) | AZ16: =INDEX($C$5:$BV$5,23) | BA16: =INDEX($C$5:$BV$5,22) | BB16: =INDEX($C$5:$BV$5,21) | BC16: =INDEX($C$5:$BV$5,20) | BD16: =INDEX($C$5:$BV$5,19) | BE16: =INDEX($C$5:$BV$5,18) | BF16: =INDEX($C$5:$BV$5,17) | BG16: =INDEX($C$5:$BV$5,16) | BH16: =INDEX($C$5:$BV$5,15) | BI16: =INDEX($C$5:$BV$5,14) | BJ16: =INDEX($C$5:$BV$5,13) | BK16: =INDEX($C$5:$BV$5,12) | BL16: =INDEX($C$5:$BV$5,11) | BM16: =INDEX($C$5:$BV$5,10) | BN16: =INDEX($C$5:$BV$5,9) | BO16: =INDEX($C$5:$BV$5,8) | BP16: =INDEX($C$5:$BV$5,7) | BQ16: =INDEX($C$5:$BV$5,6) | BR16: =INDEX($C$5:$BV$5,5) | BS16: =INDEX($C$5:$BV$5,4) | BT16: =INDEX($C$5:$BV$5,3) | BU16: =INDEX($C$5:$BV$5,2) | BV16: =INDEX($C$5:$BV$5,1)
A17: S_REACT reversed | C17: =INDEX($C$6:$BV$6,72) | D17: =INDEX($C$6:$BV$6,71) | E17: =INDEX($C$6:$BV$6,70) | F17: =INDEX($C$6:$BV$6,69) | G17: =INDEX($C$6:$BV$6,68) | H17: =INDEX($C$6:$BV$6,67) | I17: =INDEX($C$6:$BV$6,66) | J17: =INDEX($C$6:$BV$6,65) | K17: =INDEX($C$6:$BV$6,64) | L17: =INDEX($C$6:$BV$6,63) | M17: =INDEX($C$6:$BV$6,62) | N17: =INDEX($C$6:$BV$6,61) | O17: =INDEX($C$6:$BV$6,60) | P17: =INDEX($C$6:$BV$6,59) | Q17: =INDEX($C$6:$BV$6,58) | R17: =INDEX($C$6:$BV$6,57) | S17: =INDEX($C$6:$BV$6,56) | T17: =INDEX($C$6:$BV$6,55) | U17: =INDEX($C$6:$BV$6,54) | V17: =INDEX($C$6:$BV$6,53) | W17: =INDEX($C$6:$BV$6,52) | X17: =INDEX($C$6:$BV$6,51) | Y17: =INDEX($C$6:$BV$6,50) | Z17: =INDEX($C$6:$BV$6,49) | AA17: =INDEX($C$6:$BV$6,48) | AB17: =INDEX($C$6:$BV$6,47) | AC17: =INDEX($C$6:$BV$6,46) | AD17: =INDEX($C$6:$BV$6,45) | AE17: =INDEX($C$6:$BV$6,44) | AF17: =INDEX($C$6:$BV$6,43) | AG17: =INDEX($C$6:$BV$6,42) | AH17: =INDEX($C$6:$BV$6,41) | AI17: =INDEX($C$6:$BV$6,40) | AJ17: =INDEX($C$6:$BV$6,39) | AK17: =INDEX($C$6:$BV$6,38) | AL17: =INDEX($C$6:$BV$6,37) | AM17: =INDEX($C$6:$BV$6,36) | AN17: =INDEX($C$6:$BV$6,35) | AO17: =INDEX($C$6:$BV$6,34) | AP17: =INDEX($C$6:$BV$6,33) | AQ17: =INDEX($C$6:$BV$6,32) | AR17: =INDEX($C$6:$BV$6,31) | AS17: =INDEX($C$6:$BV$6,30) | AT17: =INDEX($C$6:$BV$6,29) | AU17: =INDEX($C$6:$BV$6,28) | AV17: =INDEX($C$6:$BV$6,27) | AW17: =INDEX($C$6:$BV$6,26) | AX17: =INDEX($C$6:$BV$6,25) | AY17: =INDEX($C$6:$BV$6,24) | AZ17: =INDEX($C$6:$BV$6,23) | BA17: =INDEX($C$6:$BV$6,22) | BB17: =INDEX($C$6:$BV$6,21) | BC17: =INDEX($C$6:$BV$6,20) | BD17: =INDEX($C$6:$BV$6,19) | BE17: =INDEX($C$6:$BV$6,18) | BF17: =INDEX($C$6:$BV$6,17) | BG17: =INDEX($C$6:$BV$6,16) | BH17: =INDEX($C$6:$BV$6,15) | BI17: =INDEX($C$6:$BV$6,14) | BJ17: =INDEX($C$6:$BV$6,13) | BK17: =INDEX($C$6:$BV$6,12) | BL17: =INDEX($C$6:$BV$6,11) | BM17: =INDEX($C$6:$BV$6,10) | BN17: =INDEX($C$6:$BV$6,9) | BO17: =INDEX($C$6:$BV$6,8) | BP17: =INDEX($C$6:$BV$6,7) | BQ17: =INDEX($C$6:$BV$6,6) | BR17: =INDEX($C$6:$BV$6,5) | BS17: =INDEX($C$6:$BV$6,4) | BT17: =INDEX($C$6:$BV$6,3) | BU17: =INDEX($C$6:$BV$6,2) | BV17: =INDEX($C$6:$BV$6,1)
A18: D_REACT reversed | C18: =INDEX($C$7:$BV$7,72) | D18: =INDEX($C$7:$BV$7,71) | E18: =INDEX($C$7:$BV$7,70) | F18: =INDEX($C$7:$BV$7,69) | G18: =INDEX($C$7:$BV$7,68) | H18: =INDEX($C$7:$BV$7,67) | I18: =INDEX($C$7:$BV$7,66) | J18: =INDEX($C$7:$BV$7,65) | K18: =INDEX($C$7:$BV$7,64) | L18: =INDEX($C$7:$BV$7,63) | M18: =INDEX($C$7:$BV$7,62) | N18: =INDEX($C$7:$BV$7,61) | O18: =INDEX($C$7:$BV$7,60) | P18: =INDEX($C$7:$BV$7,59) | Q18: =INDEX($C$7:$BV$7,58) | R18: =INDEX($C$7:$BV$7,57) | S18: =INDEX($C$7:$BV$7,56) | T18: =INDEX($C$7:$BV$7,55) | U18: =INDEX($C$7:$BV$7,54) | V18: =INDEX($C$7:$BV$7,53) | W18: =INDEX($C$7:$BV$7,52) | X18: =INDEX($C$7:$BV$7,51) | Y18: =INDEX($C$7:$BV$7,50) | Z18: =INDEX($C$7:$BV$7,49) | AA18: =INDEX($C$7:$BV$7,48) | AB18: =INDEX($C$7:$BV$7,47) | AC18: =INDEX($C$7:$BV$7,46) | AD18: =INDEX($C$7:$BV$7,45) | AE18: =INDEX($C$7:$BV$7,44) | AF18: =INDEX($C$7:$BV$7,43) | AG18: =INDEX($C$7:$BV$7,42) | AH18: =INDEX($C$7:$BV$7,41) | AI18: =INDEX($C$7:$BV$7,40) | AJ18: =INDEX($C$7:$BV$7,39) | AK18: =INDEX($C$7:$BV$7,38) | AL18: =INDEX($C$7:$BV$7,37) | AM18: =INDEX($C$7:$BV$7,36) | AN18: =INDEX($C$7:$BV$7,35) | AO18: =INDEX($C$7:$BV$7,34) | AP18: =INDEX($C$7:$BV$7,33) | AQ18: =INDEX($C$7:$BV$7,32) | AR18: =INDEX($C$7:$BV$7,31) | AS18: =INDEX($C$7:$BV$7,30) | AT18: =INDEX($C$7:$BV$7,29) | AU18: =INDEX($C$7:$BV$7,28) | AV18: =INDEX($C$7:$BV$7,27) | AW18: =INDEX($C$7:$BV$7,26) | AX18: =INDEX($C$7:$BV$7,25) | AY18: =INDEX($C$7:$BV$7,24) | AZ18: =INDEX($C$7:$BV$7,23) | BA18: =INDEX($C$7:$BV$7,22) | BB18: =INDEX($C$7:$BV$7,21) | BC18: =INDEX($C$7:$BV$7,20) | BD18: =INDEX($C$7:$BV$7,19) | BE18: =INDEX($C$7:$BV$7,18) | BF18: =INDEX($C$7:$BV$7,17) | BG18: =INDEX($C$7:$BV$7,16) | BH18: =INDEX($C$7:$BV$7,15) | BI18: =INDEX($C$7:$BV$7,14) | BJ18: =INDEX($C$7:$BV$7,13) | BK18: =INDEX($C$7:$BV$7,12) | BL18: =INDEX($C$7:$BV$7,11) | BM18: =INDEX($C$7:$BV$7,10) | BN18: =INDEX($C$7:$BV$7,9) | BO18: =INDEX($C$7:$BV$7,8) | BP18: =INDEX($C$7:$BV$7,7) | BQ18: =INDEX($C$7:$BV$7,6) | BR18: =INDEX($C$7:$BV$7,5) | BS18: =INDEX($C$7:$BV$7,4) | BT18: =INDEX($C$7:$BV$7,3) | BU18: =INDEX($C$7:$BV$7,2) | BV18: =INDEX($C$7:$BV$7,1)
A19: K_REACT reversed | C19: =INDEX($C$8:$BV$8,72) | D19: =INDEX($C$8:$BV$8,71) | E19: =INDEX($C$8:$BV$8,70) | F19: =INDEX($C$8:$BV$8,69) | G19: =INDEX($C$8:$BV$8,68) | H19: =INDEX($C$8:$BV$8,67) | I19: =INDEX($C$8:$BV$8,66) | J19: =INDEX($C$8:$BV$8,65) | K19: =INDEX($C$8:$BV$8,64) | L19: =INDEX($C$8:$BV$8,63) | M19: =INDEX($C$8:$BV$8,62) | N19: =INDEX($C$8:$BV$8,61) | O19: =INDEX($C$8:$BV$8,60) | P19: =INDEX($C$8:$BV$8,59) | Q19: =INDEX($C$8:$BV$8,58) | R19: =INDEX($C$8:$BV$8,57) | S19: =INDEX($C$8:$BV$8,56) | T19: =INDEX($C$8:$BV$8,55) | U19: =INDEX($C$8:$BV$8,54) | V19: =INDEX($C$8:$BV$8,53) | W19: =INDEX($C$8:$BV$8,52) | X19: =INDEX($C$8:$BV$8,51) | Y19: =INDEX($C$8:$BV$8,50) | Z19: =INDEX($C$8:$BV$8,49) | AA19: =INDEX($C$8:$BV$8,48) | AB19: =INDEX($C$8:$BV$8,47) | AC19: =INDEX($C$8:$BV$8,46) | AD19: =INDEX($C$8:$BV$8,45) | AE19: =INDEX($C$8:$BV$8,44) | AF19: =INDEX($C$8:$BV$8,43) | AG19: =INDEX($C$8:$BV$8,42) | AH19: =INDEX($C$8:$BV$8,41) | AI19: =INDEX($C$8:$BV$8,40) | AJ19: =INDEX($C$8:$BV$8,39) | AK19: =INDEX($C$8:$BV$8,38) | AL19: =INDEX($C$8:$BV$8,37) | AM19: =INDEX($C$8:$BV$8,36) | AN19: =INDEX($C$8:$BV$8,35) | AO19: =INDEX($C$8:$BV$8,34) | AP19: =INDEX($C$8:$BV$8,33) | AQ19: =INDEX($C$8:$BV$8,32) | AR19: =INDEX($C$8:$BV$8,31) | AS19: =INDEX($C$8:$BV$8,30) | AT19: =INDEX($C$8:$BV$8,29) | AU19: =INDEX($C$8:$BV$8,28) | AV19: =INDEX($C$8:$BV$8,27) | AW19: =INDEX($C$8:$BV$8,26) | AX19: =INDEX($C$8:$BV$8,25) | AY19: =INDEX($C$8:$BV$8,24) | AZ19: =INDEX($C$8:$BV$8,23) | BA19: =INDEX($C$8:$BV$8,22) | BB19: =INDEX($C$8:$BV$8,21) | BC19: =INDEX($C$8:$BV$8,20) | BD19: =INDEX($C$8:$BV$8,19) | BE19: =INDEX($C$8:$BV$8,18) | BF19: =INDEX($C$8:$BV$8,17) | BG19: =INDEX($C$8:$BV$8,16) | BH19: =INDEX($C$8:$BV$8,15) | BI19: =INDEX($C$8:$BV$8,14) | BJ19: =INDEX($C$8:$BV$8,13) | BK19: =INDEX($C$8:$BV$8,12) | BL19: =INDEX($C$8:$BV$8,11) | BM19: =INDEX($C$8:$BV$8,10) | BN19: =INDEX($C$8:$BV$8,9) | BO19: =INDEX($C$8:$BV$8,8) | BP19: =INDEX($C$8:$BV$8,7) | BQ19: =INDEX($C$8:$BV$8,6) | BR19: =INDEX($C$8:$BV$8,5) | BS19: =INDEX($C$8:$BV$8,4) | BT19: =INDEX($C$8:$BV$8,3) | BU19: =INDEX($C$8:$BV$8,2) | BV19: =INDEX($C$8:$BV$8,1)
A20: S_MONTHLY_Y1 reversed | C20: =INDEX($C$9:$BV$9,72) | D20: =INDEX($C$9:$BV$9,71) | E20: =INDEX($C$9:$BV$9,70) | F20: =INDEX($C$9:$BV$9,69) | G20: =INDEX($C$9:$BV$9,68) | H20: =INDEX($C$9:$BV$9,67) | I20: =INDEX($C$9:$BV$9,66) | J20: =INDEX($C$9:$BV$9,65) | K20: =INDEX($C$9:$BV$9,64) | L20: =INDEX($C$9:$BV$9,63) | M20: =INDEX($C$9:$BV$9,62) | N20: =INDEX($C$9:$BV$9,61) | O20: =INDEX($C$9:$BV$9,60) | P20: =INDEX($C$9:$BV$9,59) | Q20: =INDEX($C$9:$BV$9,58) | R20: =INDEX($C$9:$BV$9,57) | S20: =INDEX($C$9:$BV$9,56) | T20: =INDEX($C$9:$BV$9,55) | U20: =INDEX($C$9:$BV$9,54) | V20: =INDEX($C$9:$BV$9,53) | W20: =INDEX($C$9:$BV$9,52) | X20: =INDEX($C$9:$BV$9,51) | Y20: =INDEX($C$9:$BV$9,50) | Z20: =INDEX($C$9:$BV$9,49) | AA20: =INDEX($C$9:$BV$9,48) | AB20: =INDEX($C$9:$BV$9,47) | AC20: =INDEX($C$9:$BV$9,46) | AD20: =INDEX($C$9:$BV$9,45) | AE20: =INDEX($C$9:$BV$9,44) | AF20: =INDEX($C$9:$BV$9,43) | AG20: =INDEX($C$9:$BV$9,42) | AH20: =INDEX($C$9:$BV$9,41) | AI20: =INDEX($C$9:$BV$9,40) | AJ20: =INDEX($C$9:$BV$9,39) | AK20: =INDEX($C$9:$BV$9,38) | AL20: =INDEX($C$9:$BV$9,37) | AM20: =INDEX($C$9:$BV$9,36) | AN20: =INDEX($C$9:$BV$9,35) | AO20: =INDEX($C$9:$BV$9,34) | AP20: =INDEX($C$9:$BV$9,33) | AQ20: =INDEX($C$9:$BV$9,32) | AR20: =INDEX($C$9:$BV$9,31) | AS20: =INDEX($C$9:$BV$9,30) | AT20: =INDEX($C$9:$BV$9,29) | AU20: =INDEX($C$9:$BV$9,28) | AV20: =INDEX($C$9:$BV$9,27) | AW20: =INDEX($C$9:$BV$9,26) | AX20: =INDEX($C$9:$BV$9,25) | AY20: =INDEX($C$9:$BV$9,24) | AZ20: =INDEX($C$9:$BV$9,23) | BA20: =INDEX($C$9:$BV$9,22) | BB20: =INDEX($C$9:$BV$9,21) | BC20: =INDEX($C$9:$BV$9,20) | BD20: =INDEX($C$9:$BV$9,19) | BE20: =INDEX($C$9:$BV$9,18) | BF20: =INDEX($C$9:$BV$9,17) | BG20: =INDEX($C$9:$BV$9,16) | BH20: =INDEX($C$9:$BV$9,15) | BI20: =INDEX($C$9:$BV$9,14) | BJ20: =INDEX($C$9:$BV$9,13) | BK20: =INDEX($C$9:$BV$9,12) | BL20: =INDEX($C$9:$BV$9,11) | BM20: =INDEX($C$9:$BV$9,10) | BN20: =INDEX($C$9:$BV$9,9) | BO20: =INDEX($C$9:$BV$9,8) | BP20: =INDEX($C$9:$BV$9,7) | BQ20: =INDEX($C$9:$BV$9,6) | BR20: =INDEX($C$9:$BV$9,5) | BS20: =INDEX($C$9:$BV$9,4) | BT20: =INDEX($C$9:$BV$9,3) | BU20: =INDEX($C$9:$BV$9,2) | BV20: =INDEX($C$9:$BV$9,1)
A21: S_ANNUAL_Y1 reversed | C21: =INDEX($C$10:$BV$10,72) | D21: =INDEX($C$10:$BV$10,71) | E21: =INDEX($C$10:$BV$10,70) | F21: =INDEX($C$10:$BV$10,69) | G21: =INDEX($C$10:$BV$10,68) | H21: =INDEX($C$10:$BV$10,67) | I21: =INDEX($C$10:$BV$10,66) | J21: =INDEX($C$10:$BV$10,65) | K21: =INDEX($C$10:$BV$10,64) | L21: =INDEX($C$10:$BV$10,63) | M21: =INDEX($C$10:$BV$10,62) | N21: =INDEX($C$10:$BV$10,61) | O21: =INDEX($C$10:$BV$10,60) | P21: =INDEX($C$10:$BV$10,59) | Q21: =INDEX($C$10:$BV$10,58) | R21: =INDEX($C$10:$BV$10,57) | S21: =INDEX($C$10:$BV$10,56) | T21: =INDEX($C$10:$BV$10,55) | U21: =INDEX($C$10:$BV$10,54) | V21: =INDEX($C$10:$BV$10,53) | W21: =INDEX($C$10:$BV$10,52) | X21: =INDEX($C$10:$BV$10,51) | Y21: =INDEX($C$10:$BV$10,50) | Z21: =INDEX($C$10:$BV$10,49) | AA21: =INDEX($C$10:$BV$10,48) | AB21: =INDEX($C$10:$BV$10,47) | AC21: =INDEX($C$10:$BV$10,46) | AD21: =INDEX($C$10:$BV$10,45) | AE21: =INDEX($C$10:$BV$10,44) | AF21: =INDEX($C$10:$BV$10,43) | AG21: =INDEX($C$10:$BV$10,42) | AH21: =INDEX($C$10:$BV$10,41) | AI21: =INDEX($C$10:$BV$10,40) | AJ21: =INDEX($C$10:$BV$10,39) | AK21: =INDEX($C$10:$BV$10,38) | AL21: =INDEX($C$10:$BV$10,37) | AM21: =INDEX($C$10:$BV$10,36) | AN21: =INDEX($C$10:$BV$10,35) | AO21: =INDEX($C$10:$BV$10,34) | AP21: =INDEX($C$10:$BV$10,33) | AQ21: =INDEX($C$10:$BV$10,32) | AR21: =INDEX($C$10:$BV$10,31) | AS21: =INDEX($C$10:$BV$10,30) | AT21: =INDEX($C$10:$BV$10,29) | AU21: =INDEX($C$10:$BV$10,28) | AV21: =INDEX($C$10:$BV$10,27) | AW21: =INDEX($C$10:$BV$10,26) | AX21: =INDEX($C$10:$BV$10,25) | AY21: =INDEX($C$10:$BV$10,24) | AZ21: =INDEX($C$10:$BV$10,23) | BA21: =INDEX($C$10:$BV$10,22) | BB21: =INDEX($C$10:$BV$10,21) | BC21: =INDEX($C$10:$BV$10,20) | BD21: =INDEX($C$10:$BV$10,19) | BE21: =INDEX($C$10:$BV$10,18) | BF21: =INDEX($C$10:$BV$10,17) | BG21: =INDEX($C$10:$BV$10,16) | BH21: =INDEX($C$10:$BV$10,15) | BI21: =INDEX($C$10:$BV$10,14) | BJ21: =INDEX($C$10:$BV$10,13) | BK21: =INDEX($C$10:$BV$10,12) | BL21: =INDEX($C$10:$BV$10,11) | BM21: =INDEX($C$10:$BV$10,10) | BN21: =INDEX($C$10:$BV$10,9) | BO21: =INDEX($C$10:$BV$10,8) | BP21: =INDEX($C$10:$BV$10,7) | BQ21: =INDEX($C$10:$BV$10,6) | BR21: =INDEX($C$10:$BV$10,5) | BS21: =INDEX($C$10:$BV$10,4) | BT21: =INDEX($C$10:$BV$10,3) | BU21: =INDEX($C$10:$BV$10,2) | BV21: =INDEX($C$10:$BV$10,1)
A22: S_REACT_Y1 reversed | C22: =INDEX($C$11:$BV$11,72) | D22: =INDEX($C$11:$BV$11,71) | E22: =INDEX($C$11:$BV$11,70) | F22: =INDEX($C$11:$BV$11,69) | G22: =INDEX($C$11:$BV$11,68) | H22: =INDEX($C$11:$BV$11,67) | I22: =INDEX($C$11:$BV$11,66) | J22: =INDEX($C$11:$BV$11,65) | K22: =INDEX($C$11:$BV$11,64) | L22: =INDEX($C$11:$BV$11,63) | M22: =INDEX($C$11:$BV$11,62) | N22: =INDEX($C$11:$BV$11,61) | O22: =INDEX($C$11:$BV$11,60) | P22: =INDEX($C$11:$BV$11,59) | Q22: =INDEX($C$11:$BV$11,58) | R22: =INDEX($C$11:$BV$11,57) | S22: =INDEX($C$11:$BV$11,56) | T22: =INDEX($C$11:$BV$11,55) | U22: =INDEX($C$11:$BV$11,54) | V22: =INDEX($C$11:$BV$11,53) | W22: =INDEX($C$11:$BV$11,52) | X22: =INDEX($C$11:$BV$11,51) | Y22: =INDEX($C$11:$BV$11,50) | Z22: =INDEX($C$11:$BV$11,49) | AA22: =INDEX($C$11:$BV$11,48) | AB22: =INDEX($C$11:$BV$11,47) | AC22: =INDEX($C$11:$BV$11,46) | AD22: =INDEX($C$11:$BV$11,45) | AE22: =INDEX($C$11:$BV$11,44) | AF22: =INDEX($C$11:$BV$11,43) | AG22: =INDEX($C$11:$BV$11,42) | AH22: =INDEX($C$11:$BV$11,41) | AI22: =INDEX($C$11:$BV$11,40) | AJ22: =INDEX($C$11:$BV$11,39) | AK22: =INDEX($C$11:$BV$11,38) | AL22: =INDEX($C$11:$BV$11,37) | AM22: =INDEX($C$11:$BV$11,36) | AN22: =INDEX($C$11:$BV$11,35) | AO22: =INDEX($C$11:$BV$11,34) | AP22: =INDEX($C$11:$BV$11,33) | AQ22: =INDEX($C$11:$BV$11,32) | AR22: =INDEX($C$11:$BV$11,31) | AS22: =INDEX($C$11:$BV$11,30) | AT22: =INDEX($C$11:$BV$11,29) | AU22: =INDEX($C$11:$BV$11,28) | AV22: =INDEX($C$11:$BV$11,27) | AW22: =INDEX($C$11:$BV$11,26) | AX22: =INDEX($C$11:$BV$11,25) | AY22: =INDEX($C$11:$BV$11,24) | AZ22: =INDEX($C$11:$BV$11,23) | BA22: =INDEX($C$11:$BV$11,22) | BB22: =INDEX($C$11:$BV$11,21) | BC22: =INDEX($C$11:$BV$11,20) | BD22: =INDEX($C$11:$BV$11,19) | BE22: =INDEX($C$11:$BV$11,18) | BF22: =INDEX($C$11:$BV$11,17) | BG22: =INDEX($C$11:$BV$11,16) | BH22: =INDEX($C$11:$BV$11,15) | BI22: =INDEX($C$11:$BV$11,14) | BJ22: =INDEX($C$11:$BV$11,13) | BK22: =INDEX($C$11:$BV$11,12) | BL22: =INDEX($C$11:$BV$11,11) | BM22: =INDEX($C$11:$BV$11,10) | BN22: =INDEX($C$11:$BV$11,9) | BO22: =INDEX($C$11:$BV$11,8) | BP22: =INDEX($C$11:$BV$11,7) | BQ22: =INDEX($C$11:$BV$11,6) | BR22: =INDEX($C$11:$BV$11,5) | BS22: =INDEX($C$11:$BV$11,4) | BT22: =INDEX($C$11:$BV$11,3) | BU22: =INDEX($C$11:$BV$11,2) | BV22: =INDEX($C$11:$BV$11,1)

Sheet MAU
A1: line | B1: segment | C1: 2025-01 | D1: 2025-02 | E1: 2025-03 | F1: 2025-04 | G1: 2025-05 | H1: 2025-06 | I1: 2025-07 | J1: 2025-08 | K1: 2025-09 | L1: 2025-10 | M1: 2025-11 | N1: 2025-12 | O1: 2026-01 | P1: 2026-02 | Q1: 2026-03 | R1: 2026-04 | S1: 2026-05 | T1: 2026-06 | U1: 2026-07 | V1: 2026-08 | W1: 2026-09 | X1: 2026-10 | Y1: 2026-11 | Z1: 2026-12 | AA1: 2027-01 | AB1: 2027-02 | AC1: 2027-03 | AD1: 2027-04 | AE1: 2027-05 | AF1: 2027-06 | AG1: 2027-07 | AH1: 2027-08 | AI1: 2027-09 | AJ1: 2027-10 | AK1: 2027-11 | AL1: 2027-12 | AM1: 2028-01 | AN1: 2028-02 | AO1: 2028-03 | AP1: 2028-04 | AQ1: 2028-05 | AR1: 2028-06 | AS1: 2028-07 | AT1: 2028-08 | AU1: 2028-09 | AV1: 2028-10 | AW1: 2028-11 | AX1: 2028-12 | AY1: 2029-01 | AZ1: 2029-02 | BA1: 2029-03 | BB1: 2029-04 | BC1: 2029-05 | BD1: 2029-06 | BE1: 2029-07 | BF1: 2029-08 | BG1: 2029-09 | BH1: 2029-10 | BI1: 2029-11 | BJ1: 2029-12 | BK1: 2030-01 | BL1: 2030-02 | BM1: 2030-03 | BN1: 2030-04 | BO1: 2030-05 | BP1: 2030-06 | BQ1: 2030-07 | BR1: 2030-08 | BS1: 2030-09 | BT1: 2030-10 | BU1: 2030-11 | BV1: 2030-12
A2: month index (0 = Jan 2025) | C2: 0 | D2: 1 | E2: 2 | F2: 3 | G2: 4 | H2: 5 | I2: 6 | J2: 7 | K2: 8 | L2: 9 | M2: 10 | N2: 11 | O2: 12 | P2: 13 | Q2: 14 | R2: 15 | S2: 16 | T2: 17 | U2: 18 | V2: 19 | W2: 20 | X2: 21 | Y2: 22 | Z2: 23 | AA2: 24 | AB2: 25 | AC2: 26 | AD2: 27 | AE2: 28 | AF2: 29 | AG2: 30 | AH2: 31 | AI2: 32 | AJ2: 33 | AK2: 34 | AL2: 35 | AM2: 36 | AN2: 37 | AO2: 38 | AP2: 39 | AQ2: 40 | AR2: 41 | AS2: 42 | AT2: 43 | AU2: 44 | AV2: 45 | AW2: 46 | AX2: 47 | AY2: 48 | AZ2: 49 | BA2: 50 | BB2: 51 | BC2: 52 | BD2: 53 | BE2: 54 | BF2: 55 | BG2: 56 | BH2: 57 | BI2: 58 | BJ2: 59 | BK2: 60 | BL2: 61 | BM2: 62 | BN2: 63 | BO2: 64 | BP2: 65 | BQ2: 66 | BR2: 67 | BS2: 68 | BT2: 69 | BU2: 70 | BV2: 71
A3: MAU total | B3: all | C3: =Params!$B$2 | D3: =C3*(1+(Params!$B$3+(Params!$B$4-Params!$B$3)*INT(D$2/12)/5))^(1/12) | E3: =D3*(1+(Params!$B$3+(Params!$B$4-Params!$B$3)*INT(E$2/12)/5))^(1/12) | F3: =E3*(1+(Params!$B$3+(Params!$B$4-Params!$B$3)*INT(F$2/12)/5))^(1/12) | G3: =F3*(1+(Params!$B$3+(Params!$B$4-Params!$B$3)*INT(G$2/12)/5))^(1/12) | H3: =G3*(1+(Params!$B$3+(Params!$B$4-Params!$B$3)*INT(H$2/12)/5))^(1/12) | I3: =H3*(1+(Params!$B$3+(Params!$B$4-Params!$B$3)*INT(I$2/12)/5))^(1/12) | J3: =I3*(1+(Params!$B$3+(Params!$B$4-Params!$B$3)*INT(J$2/12)/5))^(1/12) | K3: =J3*(1+(Params!$B$3+(Params!$B$4-Params!$B$3)*INT(K$2/12)/5))^(1/12) | ... BV3: =BU3*(1+(Params!$B$3+(Params!$B$4-Params!$B$3)*INT(BV$2/12)/5))^(1/12)
A4: MAU | B4: US_CA | C4: =C$3*Params!$B$31 | D4: =D$3*Params!$B$31 | E4: =E$3*Params!$B$31 | F4: =F$3*Params!$B$31 | G4: =G$3*Params!$B$31 | H4: =H$3*Params!$B$31 | I4: =I$3*Params!$B$31 | J4: =J$3*Params!$B$31 | ... BV4: =BV$3*Params!$B$31
A5: MAU | B5: EUROPE | C5: =C$3*Params!$B$32 | D5: =D$3*Params!$B$32 | E5: =E$3*Params!$B$32 | F5: =F$3*Params!$B$32 | G5: =G$3*Params!$B$32 | H5: =H$3*Params!$B$32 | I5: =I$3*Params!$B$32 | J5: =J$3*Params!$B$32 | ... BV5: =BV$3*Params!$B$32
A6: MAU | B6: LATAM | C6: =C$3*Params!$B$33 | D6: =D$3*Params!$B$33 | E6: =E$3*Params!$B$33 | F6: =F$3*Params!$B$33 | G6: =G$3*Params!$B$33 | H6: =H$3*Params!$B$33 | I6: =I$3*Params!$B$33 | J6: =J$3*Params!$B$33 | ... BV6: =BV$3*Params!$B$33
A7: MAU | B7: APAC | C7: =C$3*Params!$B$34 | D7: =D$3*Params!$B$34 | E7: =E$3*Params!$B$34 | F7: =F$3*Params!$B$34 | G7: =G$3*Params!$B$34 | H7: =H$3*Params!$B$34 | I7: =I$3*Params!$B$34 | J7: =J$3*Params!$B$34 | ... BV7: =BV$3*Params!$B$34
A8: MAU | B8: ROW | C8: =C$3*Params!$B$35 | D8: =D$3*Params!$B$35 | E8: =E$3*Params!$B$35 | F8: =F$3*Params!$B$35 | G8: =G$3*Params!$B$35 | H8: =H$3*Params!$B$35 | I8: =I$3*Params!$B$35 | J8: =J$3*Params!$B$35 | ... BV8: =BV$3*Params!$B$35

Sheet Prices
A1: region | B1: plan | C1: list $/mo | D1: x regional index | E1: after discount & VAT | F1: keep after fees (yr 1) | G1: keep after fees (later) | H1: net $/mo (yr 1) | I1: net $/mo (later)
A2: US_CA | B2: NITRO_M | C2: =Params!$B$79/Params!$B$83 | D2: =C2*Params!$B$41 | E2: =D2*(1-Params!$B$22)*(1-Params!$B$46) | F2: =Params!$B$56*(1-Params!$B$23)+Params!$B$57*(1-Params!$B$24)+Params!$B$58*(1-Params!$B$26) | G2: =Params!$B$56*(1-Params!$B$23)+Params!$B$57*(1-Params!$B$25)+Params!$B$58*(1-Params!$B$26) | H2: =E2*F2 | I2: =E2*G2
A3: US_CA | B3: NITRO_A | C3: =Params!$B$80/Params!$B$84 | D3: =C3*Params!$B$41 | E3: =D3*(1-Params!$B$22)*(1-Params!$B$46) | F3: =Params!$B$56*(1-Params!$B$23)+Params!$B$57*(1-Params!$B$24)+Params!$B$58*(1-Params!$B$26) | G3: =Params!$B$56*(1-Params!$B$23)+Params!$B$57*(1-Params!$B$25)+Params!$B$58*(1-Params!$B$26) | H3: =E3*F3 | I3: =E3*G3
A4: US_CA | B4: BASIC_M | C4: =Params!$B$81/Params!$B$85 | D4: =C4*Params!$B$41 | E4: =D4*(1-Params!$B$22)*(1-Params!$B$46) | F4: =Params!$B$56*(1-Params!$B$23)+Params!$B$57*(1-Params!$B$24)+Params!$B$58*(1-Params!$B$26) | G4: =Params!$B$56*(1-Params!$B$23)+Params!$B$57*(1-Params!$B$25)+Params!$B$58*(1-Params!$B$26) | H4: =E4*F4 | I4: =E4*G4
A5: US_CA | B5: BASIC_A | C5: =Params!$B$82/Params!$B$86 | D5: =C5*Params!$B$41 | E5: =D5*(1-Params!$B$22)*(1-Params!$B$46) | F5: =Params!$B$56*(1-Params!$B$23)+Params!$B$57*(1-Params!$B$24)+Params!$B$58*(1-Params!$B$26) | G5: =Params!$B$56*(1-Params!$B$23)+Params!$B$57*(1-Params!$B$25)+Params!$B$58*(1-Params!$B$26) | H5: =E5*F5 | I5: =E5*G5
A6: EUROPE | B6: NITRO_M | C6: =Params!$B$79/Params!$B$83 | D6: =C6*Params!$B$42 | E6: =D6*(1-Params!$B$22)*(1-Params!$B$47) | F6: =Params!$B$59*(1-Params!$B$23)+Params!$B$60*(1-Params!$B$24)+Params!$B$61*(1-Params!$B$26) | G6: =Params!$B$59*(1-Params!$B$23)+Params!$B$60*(1-Params!$B$25)+Params!$B$61*(1-Params!$B$26) | H6: =E6*F6 | I6: =E6*G6
A7: EUROPE | B7: NITRO_A | C7: =Params!$B$80/Params!$B$84 | D7: =C7*Params!$B$42 | E7: =D7*(1-Params!$B$22)*(1-Params!$B$47) | F7: =Params!$B$59*(1-Params!$B$23)+Params!$B$60*(1-Params!$B$24)+Params!$B$61*(1-Params!$B$26) | G7: =Params!$B$59*(1-Params!$B$23)+Params!$B$60*(1-Params!$B$25)+Params!$B$61*(1-Params!$B$26) | H7: =E7*F7 | I7: =E7*G7
A8: EUROPE | B8: BASIC_M | C8: =Params!$B$81/Params!$B$85 | D8: =C8*Params!$B$42 | E8: =D8*(1-Params!$B$22)*(1-Params!$B$47) | F8: =Params!$B$59*(1-Params!$B$23)+Params!$B$60*(1-Params!$B$24)+Params!$B$61*(1-Params!$B$26) | G8: =Params!$B$59*(1-Params!$B$23)+Params!$B$60*(1-Params!$B$25)+Params!$B$61*(1-Params!$B$26) | H8: =E8*F8 | I8: =E8*G8
A9: EUROPE | B9: BASIC_A | C9: =Params!$B$82/Params!$B$86 | D9: =C9*Params!$B$42 | E9: =D9*(1-Params!$B$22)*(1-Params!$B$47) | F9: =Params!$B$59*(1-Params!$B$23)+Params!$B$60*(1-Params!$B$24)+Params!$B$61*(1-Params!$B$26) | G9: =Params!$B$59*(1-Params!$B$23)+Params!$B$60*(1-Params!$B$25)+Params!$B$61*(1-Params!$B$26) | H9: =E9*F9 | I9: =E9*G9
A10: LATAM | B10: NITRO_M | C10: =Params!$B$79/Params!$B$83 | D10: =C10*Params!$B$43 | E10: =D10*(1-Params!$B$22)*(1-Params!$B$48) | F10: =Params!$B$62*(1-Params!$B$23)+Params!$B$63*(1-Params!$B$24)+Params!$B$64*(1-Params!$B$26) | G10: =Params!$B$62*(1-Params!$B$23)+Params!$B$63*(1-Params!$B$25)+Params!$B$64*(1-Params!$B$26) | H10: =E10*F10 | I10: =E10*G10
A11: LATAM | B11: NITRO_A | C11: =Params!$B$80/Params!$B$84 | D11: =C11*Params!$B$43 | E11: =D11*(1-Params!$B$22)*(1-Params!$B$48) | F11: =Params!$B$62*(1-Params!$B$23)+Params!$B$63*(1-Params!$B$24)+Params!$B$64*(1-Params!$B$26) | G11: =Params!$B$62*(1-Params!$B$23)+Params!$B$63*(1-Params!$B$25)+Params!$B$64*(1-Params!$B$26) | H11: =E11*F11 | I11: =E11*G11
A12: LATAM | B12: BASIC_M | C12: =Params!$B$81/Params!$B$85 | D12: =C12*Params!$B$43 | E12: =D12*(1-Params!$B$22)*(1-Params!$B$48) | F12: =Params!$B$62*(1-Params!$B$23)+Params!$B$63*(1-Params!$B$24)+Params!$B$64*(1-Params!$B$26) | G12: =Params!$B$62*(1-Params!$B$23)+Params!$B$63*(1-Params!$B$25)+Params!$B$64*(1-Params!$B$26) | H12: =E12*F12 | I12: =E12*G12
A13: LATAM | B13: BASIC_A | C13: =Params!$B$82/Params!$B$86 | D13: =C13*Params!$B$43 | E13: =D13*(1-Params!$B$22)*(1-Params!$B$48) | F13: =Params!$B$62*(1-Params!$B$23)+Params!$B$63*(1-Params!$B$24)+Params!$B$64*(1-Params!$B$26) | G13: =Params!$B$62*(1-Params!$B$23)+Params!$B$63*(1-Params!$B$25)+Params!$B$64*(1-Params!$B$26) | H13: =E13*F13 | I13: =E13*G13
A14: APAC | B14: NITRO_M | C14: =Params!$B$79/Params!$B$83 | D14: =C14*Params!$B$44 | E14: =D14*(1-Params!$B$22)*(1-Params!$B$49) | F14: =Params!$B$65*(1-Params!$B$23)+Params!$B$66*(1-Params!$B$24)+Params!$B$67*(1-Params!$B$26) | G14: =Params!$B$65*(1-Params!$B$23)+Params!$B$66*(1-Params!$B$25)+Params!$B$67*(1-Params!$B$26) | H14: =E14*F14 | I14: =E14*G14
A15: APAC | B15: NITRO_A | C15: =Params!$B$80/Params!$B$84 | D15: =C15*Params!$B$44 | E15: =D15*(1-Params!$B$22)*(1-Params!$B$49) | F15: =Params!$B$65*(1-Params!$B$23)+Params!$B$66*(1-Params!$B$24)+Params!$B$67*(1-Params!$B$26) | G15: =Params!$B$65*(1-Params!$B$23)+Params!$B$66*(1-Params!$B$25)+Params!$B$67*(1-Params!$B$26) | H15: =E15*F15 | I15: =E15*G15
A16: APAC | B16: BASIC_M | C16: =Params!$B$81/Params!$B$85 | D16: =C16*Params!$B$44 | E16: =D16*(1-Params!$B$22)*(1-Params!$B$49) | F16: =Params!$B$65*(1-Params!$B$23)+Params!$B$66*(1-Params!$B$24)+Params!$B$67*(1-Params!$B$26) | G16: =Params!$B$65*(1-Params!$B$23)+Params!$B$66*(1-Params!$B$25)+Params!$B$67*(1-Params!$B$26) | H16: =E16*F16 | I16: =E16*G16
A17: APAC | B17: BASIC_A | C17: =Params!$B$82/Params!$B$86 | D17: =C17*Params!$B$44 | E17: =D17*(1-Params!$B$22)*(1-Params!$B$49) | F17: =Params!$B$65*(1-Params!$B$23)+Params!$B$66*(1-Params!$B$24)+Params!$B$67*(1-Params!$B$26) | G17: =Params!$B$65*(1-Params!$B$23)+Params!$B$66*(1-Params!$B$25)+Params!$B$67*(1-Params!$B$26) | H17: =E17*F17 | I17: =E17*G17
A18: ROW | B18: NITRO_M | C18: =Params!$B$79/Params!$B$83 | D18: =C18*Params!$B$45 | E18: =D18*(1-Params!$B$22)*(1-Params!$B$50) | F18: =Params!$B$68*(1-Params!$B$23)+Params!$B$69*(1-Params!$B$24)+Params!$B$70*(1-Params!$B$26) | G18: =Params!$B$68*(1-Params!$B$23)+Params!$B$69*(1-Params!$B$25)+Params!$B$70*(1-Params!$B$26) | H18: =E18*F18 | I18: =E18*G18
A19: ROW | B19: NITRO_A | C19: =Params!$B$80/Params!$B$84 | D19: =C19*Params!$B$45 | E19: =D19*(1-Params!$B$22)*(1-Params!$B$50) | F19: =Params!$B$68*(1-Params!$B$23)+Params!$B$69*(1-Params!$B$24)+Params!$B$70*(1-Params!$B$26) | G19: =Params!$B$68*(1-Params!$B$23)+Params!$B$69*(1-Params!$B$25)+Params!$B$70*(1-Params!$B$26) | H19: =E19*F19 | I19: =E19*G19
A20: ROW | B20: BASIC_M | C20: =Params!$B$81/Params!$B$85 | D20: =C20*Params!$B$45 | E20: =D20*(1-Params!$B$22)*(1-Params!$B$50) | F20: =Params!$B$68*(1-Params!$B$23)+Params!$B$69*(1-Params!$B$24)+Params!$B$70*(1-Params!$B$26) | G20: =Params!$B$68*(1-Params!$B$23)+Params!$B$69*(1-Params!$B$25)+Params!$B$70*(1-Params!$B$26) | H20: =E20*F20 | I20: =E20*G20
A21: ROW | B21: BASIC_A | C21: =Params!$B$82/Params!$B$86 | D21: =C21*Params!$B$45 | E21: =D21*(1-Params!$B$22)*(1-Params!$B$50) | F21: =Params!$B$68*(1-Params!$B$23)+Params!$B$69*(1-Params!$B$24)+Params!$B$70*(1-Params!$B$26) | G21: =Params!$B$68*(1-Params!$B$23)+Params!$B$69*(1-Params!$B$25)+Params!$B$70*(1-Params!$B$26) | H21: =E21*F21 | I21: =E21*G21

Sheet Adds
A1: line | B1: segment | C1: 2025-01 | D1: 2025-02 | E1: 2025-03 | F1: 2025-04 | G1: 2025-05 | H1: 2025-06 | I1: 2025-07 | J1: 2025-08 | K1: 2025-09 | L1: 2025-10 | M1: 2025-11 | N1: 2025-12 | O1: 2026-01 | P1: 2026-02 | Q1: 2026-03 | R1: 2026-04 | S1: 2026-05 | T1: 2026-06 | U1: 2026-07 | V1: 2026-08 | W1: 2026-09 | X1: 2026-10 | Y1: 2026-11 | Z1: 2026-12 | AA1: 2027-01 | AB1: 2027-02 | AC1: 2027-03 | AD1: 2027-04 | AE1: 2027-05 | AF1: 2027-06 | AG1: 2027-07 | AH1: 2027-08 | AI1: 2027-09 | AJ1: 2027-10 | AK1: 2027-11 | AL1: 2027-12 | AM1: 2028-01 | AN1: 2028-02 | AO1: 2028-03 | AP1: 2028-04 | AQ1: 2028-05 | AR1: 2028-06 | AS1: 2028-07 | AT1: 2028-08 | AU1: 2028-09 | AV1: 2028-10 | AW1: 2028-11 | AX1: 2028-12 | AY1: 2029-01 | AZ1: 2029-02 | BA1: 2029-03 | BB1: 2029-04 | BC1: 2029-05 | BD1: 2029-06 | BE1: 2029-07 | BF1: 2029-08 | BG1: 2029-09 | BH1: 2029-10 | BI1: 2029-11 | BJ1: 2029-12 | BK1: 2030-01 | BL1: 2030-02 | BM1: 2030-03 | BN1: 2030-04 | BO1: 2030-05 | BP1: 2030-06 | BQ1: 2030-07 | BR1: 2030-08 | BS1: 2030-09 | BT1: 2030-10 | BU1: 2030-11 | BV1: 2030-12
A2: month index (0 = Jan 2025) | C2: 0 | D2: 1 | E2: 2 | F2: 3 | G2: 4 | H2: 5 | I2: 6 | J2: 7 | K2: 8 | L2: 9 | M2: 10 | N2: 11 | O2: 12 | P2: 13 | Q2: 14 | R2: 15 | S2: 16 | T2: 17 | U2: 18 | V2: 19 | W2: 20 | X2: 21 | Y2: 22 | Z2: 23 | AA2: 24 | AB2: 25 | AC2: 26 | AD2: 27 | AE2: 28 | AF2: 29 | AG2: 30 | AH2: 31 | AI2: 32 | AJ2: 33 | AK2: 34 | AL2: 35 | AM2: 36 | AN2: 37 | AO2: 38 | AP2: 39 | AQ2: 40 | AR2: 41 | AS2: 42 | AT2: 43 | AU2: 44 | AV2: 45 | AW2: 46 | AX2: 47 | AY2: 48 | AZ2: 49 | BA2: 50 | BB2: 51 | BC2: 52 | BD2: 53 | BE2: 54 | BF2: 55 | BG2: 56 | BH2: 57 | BI2: 58 | BJ2: 59 | BK2: 60 | BL2: 61 | BM2: 62 | BN2: 63 | BO2: 64 | BP2: 65 | BQ2: 66 | BR2: 67 | BS2: 68 | BT2: 69 | BU2: 70 | BV2: 71
A3: gross adds | B3: US_CA|NITRO_M | C3: =MAU!C4*Params!$B$36*Params!$B$5*Params!$B$87*Params!$B$71 | D3: =MAU!D4*Params!$B$36*Params!$B$5*Params!$B$87*Params!$B$71 | E3: =MAU!E4*Params!$B$36*Params!$B$5*Params!$B$87*Params!$B$71 | F3: =MAU!F4*Params!$B$36*Params!$B$5*Params!$B$87*Params!$B$71 | G3: =MAU!G4*Params!$B$36*Params!$B$5*Params!$B$87*Params!$B$71 | H3: =MAU!H4*Params!$B$36*Params!$B$5*Params!$B$87*Params!$B$71 | I3: =MAU!I4*Params!$B$36*Params!$B$5*Params!$B$87*Params!$B$71 | J3: =MAU!J4*Params!$B$36*Params!$B$5*Params!$B$87*Params!$B$71 | ... BV3: =MAU!BV4*Params!$B$36*Params!$B$5*Params!$B$87*Params!$B$71
A4: trial starts | B4: US_CA|NITRO_M | C4: =C3*Params!$B$6 | D4: =D3*Params!$B$6 | E4: =E3*Params!$B$6 | F4: =F3*Params!$B$6 | G4: =G3*Params!$B$6 | H4: =H3*Params!$B$6 | I4: =I3*Params!$B$6 | J4: =J3*Params!$B$6 | ... BV4: =BV3*Params!$B$6
A5: direct paid starts | B5: US_CA|NITRO_M | C5: =C3-C4 | D5: =D3-D4 | E5: =E3-E4 | F5: =F3-F4 | G5: =G3-G4 | H5: =H3-H4 | I5: =I3-I4 | J5: =J3-J4 | ... BV5: =BV3-BV4
A6: trials ending | B6: US_CA|NITRO_M | C6: =IF(C$2>=Params!$B$7,INDEX($C$4:$BV$4,C$2-Params!$B$7+1),0) | D6: =IF(D$2>=Params!$B$7,INDEX($C$4:$BV$4,D$2-Params!$B$7+1),0) | E6: =IF(E$2>=Params!$B$7,INDEX($C$4:$BV$4,E$2-Params!$B$7+1),0) | F6: =IF(F$2>=Params!$B$7,INDEX($C$4:$BV$4,F$2-Params!$B$7+1),0) | G6: =IF(G$2>=Params!$B$7,INDEX($C$4:$BV$4,G$2-Params!$B$7+1),0) | H6: =IF(H$2>=Params!$B$7,INDEX($C$4:$BV$4,H$2-Params!$B$7+1),0) | I6: =IF(I$2>=Params!$B$7,INDEX($C$4:$BV$4,I$2-Params!$B$7+1),0) | J6: =IF(J$2>=Params!$B$7,INDEX($C$4:$BV$4,J$2-Params!$B$7+1),0) | ... BV6: =IF(BV$2>=Params!$B$7,INDEX($C$4:$BV$4,BV$2-Params!$B$7+1),0)
A7: trials converted | B7: US_CA|NITRO_M | C7: =C6*Params!$B$8 | D7: =D6*Params!$B$8 | E7: =E6*Params!$B$8 | F7: =F6*Params!$B$8 | G7: =G6*Params!$B$8 | H7: =H6*Params!$B$8 | I7: =I6*Params!$B$8 | J7: =J6*Params!$B$8 | ... BV7: =BV6*Params!$B$8
A8: trials lost | B8: US_CA|NITRO_M | C8: =C6-C7 | D8: =D6-D7 | E8: =E6-E7 | F8: =F6-F7 | G8: =G6-G7 | H8: =H6-H7 | I8: =I6-I7 | J8: =J6-J7 | ... BV8: =BV6-BV7
A9: cum trial starts | B9: US_CA|NITRO_M | C9: =SUM($C4:C4) | D9: =SUM($C4:D4) | E9: =SUM($C4:E4) | F9: =SUM($C4:F4) | G9: =SUM($C4:G4) | H9: =SUM($C4:H4) | I9: =SUM($C4:I4) | J9: =SUM($C4:J4) | ... BV9: =SUM($C4:BV4)
A10: cum trials ending | B10: US_CA|NITRO_M | C10: =SUM($C6:C6) | D10: =SUM($C6:D6) | E10: =SUM($C6:E6) | F10: =SUM($C6:F6) | G10: =SUM($C6:G6) | H10: =SUM($C6:H6) | I10: =SUM($C6:I6) | J10: =SUM($C6:J6) | ... BV10: =SUM($C6:BV6)
A11: trials active | B11: US_CA|NITRO_M | C11: =C9-C10 | D11: =D9-D10 | E11: =E9-E10 | F11: =F9-F10 | G11: =G9-G10 | H11: =H9-H10 | I11: =I9-I10 | J11: =J9-J10 | ... BV11: =BV9-BV10
A12: paid starts | B12: US_CA|NITRO_M | C12: =C5+C7 | D12: =D5+D7 | E12: =E5+E7 | F12: =F5+F7 | G12: =G5+G7 | H12: =H5+H7 | I12: =I5+I7 | J12: =J5+J7 | ... BV12: =BV5+BV7
A14: gross adds | B14: US_CA|NITRO_A | C14: =MAU!C4*Params!$B$36*Params!$B$5*Params!$B$87*Params!$B$72 | D14: =MAU!D4*Params!$B$36*Params!$B$5*Params!$B$87*Params!$B$72 | E14: =MAU!E4*Params!$B$36*Params!$B$5*Params!$B$87*Params!$B$72 | F14: =MAU!F4*Params!$B$36*Params!$B$5*Params!$B$87*Params!$B$72 | G14: =MAU!G4*Params!$B$36*Params!$B$5*Params!$B$87*Params!$B$72 | H14: =MAU!H4*Params!$B$36*Params!$B$5*Params!$B$87*Params!$B$72 | I14: =MAU!I4*Params!$B$36*Params!$B$5*Params!$B$87*Params!$B$72 | J14: =MAU!J4*Params!$B$36*Params!$B$5*Params!$B$87*Params!$B$72 | ... BV14: =MAU!BV4*Params!$B$36*Params!$B$5*Params!$B$87*Params!$B$72
A15: trial starts | B15: US_CA|NITRO_A | C15: =C14*Params!$B$6 | D15: =D14*Params!$B$6 | E15: =E14*Params!$B$6 | F15: =F14*Params!$B$6 | G15: =G14*Params!$B$6 | H15: =H14*Params!$B$6 | I15: =I14*Params!$B$6 | J15: =J14*Params!$B$6 | ... BV15: =BV14*Params!$B$6
A16: direct paid starts | B16: US_CA|NITRO_A | C16: =C14-C15 | D16: =D14-D15 | E16: =E14-E15 | F16: =F14-F15 | G16: =G14-G15 | H16: =H14-H15 | I16: =I14-I15 | J16: =J14-J15 | ... BV16: =BV14-BV15
A17: trials ending | B17: US_CA|NITRO_A | C17: =IF(C$2>=Params!$B$7,INDEX($C$15:$BV$15,C$2-Params!$B$7+1),0) | D17: =IF(D$2>=Params!$B$7,INDEX($C$15:$BV$15,D$2-Params!$B$7+1),0) | E17: =IF(E$2>=Params!$B$7,INDEX($C$15:$BV$15,E$2-Params!$B$7+1),0) | F17: =IF(F$2>=Params!$B$7,INDEX($C$15:$BV$15,F$2-Params!$B$7+1),0) | G17: =IF(G$2>=Params!$B$7,INDEX($C$15:$BV$15,G$2-Params!$B$7+1),0) | H17: =IF(H$2>=Params!$B$7,INDEX($C$15:$BV$15,H$2-Params!$B$7+1),0) | I17: =IF(I$2>=Params!$B$7,INDEX($C$15:$BV$15,I$2-Params!$B$7+1),0) | J17: =IF(J$2>=Params!$B$7,INDEX($C$15:$BV$15,J$2-Params!$B$7+1),0) | ... BV17: =IF(BV$2>=Params!$B$7,INDEX($C$15:$BV$15,BV$2-Params!$B$7+1),0)
A18: trials converted | B18: US_CA|NITRO_A | C18: =C17*Params!$B$8 | D18: =D17*Params!$B$8 | E18: =E17*Params!$B$8 | F18: =F17*Params!$B$8 | G18: =G17*Params!$B$8 | H18: =H17*Params!$B$8 | I18: =I17*Params!$B$8 | J18: =J17*Params!$B$8 | ... BV18: =BV17*Params!$B$8
A19: trials lost | B19: US_CA|NITRO_A | C19: =C17-C18 | D19: =D17-D18 | E19: =E17-E18 | F19: =F17-F18 | G19: =G17-G18 | H19: =H17-H18 | I19: =I17-I18 | J19: =J17-J18 | ... BV19: =BV17-BV18
A20: cum trial starts | B20: US_CA|NITRO_A | C20: =SUM($C15:C15) | D20: =SUM($C15:D15) | E20: =SUM($C15:E15) | F20: =SUM($C15:F15) | G20: =SUM($C15:G15) | H20: =SUM($C15:H15) | I20: =SUM($C15:I15) | J20: =SUM($C15:J15) | ... BV20: =SUM($C15:BV15)
A21: cum trials ending | B21: US_CA|NITRO_A | C21: =SUM($C17:C17) | D21: =SUM($C17:D17) | E21: =SUM($C17:E17) | F21: =SUM($C17:F17) | G21: =SUM($C17:G17) | H21: =SUM($C17:H17) | I21: =SUM($C17:I17) | J21: =SUM($C17:J17) | ... BV21: =SUM($C17:BV17)
A22: trials active | B22: US_CA|NITRO_A | C22: =C20-C21 | D22: =D20-D21 | E22: =E20-E21 | F22: =F20-F21 | G22: =G20-G21 | H22: =H20-H21 | I22: =I20-I21 | J22: =J20-J21 | ... BV22: =BV20-BV21
A23: paid starts | B23: US_CA|NITRO_A | C23: =C16+C18 | D23: =D16+D18 | E23: =E16+E18 | F23: =F16+F18 | G23: =G16+G18 | H23: =H16+H18 | I23: =I16+I18 | J23: =J16+J18 | ... BV23: =BV16+BV18
A25: gross adds | B25: US_CA|BASIC_M | C25: =MAU!C4*Params!$B$36*Params!$B$5*Params!$B$87*Params!$B$73 | D25: =MAU!D4*Params!$B$36*Params!$B$5*Params!$B$87*Params!$B$73 | E25: =MAU!E4*Params!$B$36*Params!$B$5*Params!$B$87*Params!$B$73 | F25: =MAU!F4*Params!$B$36*Params!$B$5*Params!$B$87*Params!$B$73 | G25: =MAU!G4*Params!$B$36*Params!$B$5*Params!$B$87*Params!$B$73 | H25: =MAU!H4*Params!$B$36*Params!$B$5*Params!$B$87*Params!$B$73 | I25: =MAU!I4*Params!$B$36*Params!$B$5*Params!$B$87*Params!$B$73 | J25: =MAU!J4*Params!$B$36*Params!$B$5*Params!$B$87*Params!$B$73 | ... BV25: =MAU!BV4*Params!$B$36*Params!$B$5*Params!$B$87*Params!$B$73
A26: trial starts | B26: US_CA|BASIC_M | C26: =C25*Params!$B$6 | D26: =D25*Params!$B$6 | E26: =E25*Params!$B$6 | F26: =F25*Params!$B$6 | G26: =G25*Params!$B$6 | H26: =H25*Params!$B$6 | I26: =I25*Params!$B$6 | J26: =J25*Params!$B$6 | ... BV26: =BV25*Params!$B$6
A27: direct paid starts | B27: US_CA|BASIC_M | C27: =C25-C26 | D27: =D25-D26 | E27: =E25-E26 | F27: =F25-F26 | G27: =G25-G26 | H27: =H25-H26 | I27: =I25-I26 | J27: =J25-J26 | ... BV27: =BV25-BV26
A28: trials ending | B28: US_CA|BASIC_M | C28: =IF(C$2>=Params!$B$7,INDEX($C$26:$BV$26,C$2-Params!$B$7+1),0) | D28: =IF(D$2>=Params!$B$7,INDEX($C$26:$BV$26,D$2-Params!$B$7+1),0) | E28: =IF(E$2>=Params!$B$7,INDEX($C$26:$BV$26,E$2-Params!$B$7+1),0) | F28: =IF(F$2>=Params!$B$7,INDEX($C$26:$BV$26,F$2-Params!$B$7+1),0) | G28: =IF(G$2>=Params!$B$7,INDEX($C$26:$BV$26,G$2-Params!$B$7+1),0) | H28: =IF(H$2>=Params!$B$7,INDEX($C$26:$BV$26,H$2-Params!$B$7+1),0) | I28: =IF(I$2>=Params!$B$7,INDEX($C$26:$BV$26,I$2-Params!$B$7+1),0) | J28: =IF(J$2>=Params!$B$7,INDEX($C$26:$BV$26,J$2-Params!$B$7+1),0) | ... BV28: =IF(BV$2>=Params!$B$7,INDEX($C$26:$BV$26,BV$2-Params!$B$7+1),0)
A29: trials converted | B29: US_CA|BASIC_M | C29: =C28*Params!$B$8 | D29: =D28*Params!$B$8 | E29: =E28*Params!$B$8 | F29: =F28*Params!$B$8 | G29: =G28*Params!$B$8 | H29: =H28*Params!$B$8 | I29: =I28*Params!$B$8 | J29: =J28*Params!$B$8 | ... BV29: =BV28*Params!$B$8
A30: trials lost | B30: US_CA|BASIC_M | C30: =C28-C29 | D30: =D28-D29 | E30: =E28-E29 | F30: =F28-F29 | G30: =G28-G29 | H30: =H28-H29 | I30: =I28-I29 | J30: =J28-J29 | ... BV30: =BV28-BV29
A31: cum trial starts | B31: US_CA|BASIC_M | C31: =SUM($C26:C26) | D31: =SUM($C26:D26) | E31: =SUM($C26:E26) | F31: =SUM($C26:F26) | G31: =SUM($C26:G26) | H31: =SUM($C26:H26) | I31: =SUM($C26:I26) | J31: =SUM($C26:J26) | ... BV31: =SUM($C26:BV26)
A32: cum trials ending | B32: US_CA|BASIC_M | C32: =SUM($C28:C28) | D32: =SUM($C28:D28) | E32: =SUM($C28:E28) | F32: =SUM($C28:F28) | G32: =SUM($C28:G28) | H32: =SUM($C28:H28) | I32: =SUM($C28:I28) | J32: =SUM($C28:J28) | ... BV32: =SUM($C28:BV28)
A33: trials active | B33: US_CA|BASIC_M | C33: =C31-C32 | D33: =D31-D32 | E33: =E31-E32 | F33: =F31-F32 | G33: =G31-G32 | H33: =H31-H32 | I33: =I31-I32 | J33: =J31-J32 | ... BV33: =BV31-BV32
A34: paid starts | B34: US_CA|BASIC_M | C34: =C27+C29 | D34: =D27+D29 | E34: =E27+E29 | F34: =F27+F29 | G34: =G27+G29 | H34: =H27+H29 | I34: =I27+I29 | J34: =J27+J29 | ... BV34: =BV27+BV29
